Workbook

Sheet StartHere
A1: Workflow Steps
A2: 1. Complete 'Me' first
A3: 2. Interview Mum & Dad separately
A4: 3. Enforce Max-2-Essential rule
A5: 4. Review DiscussionSummary
A6: 5. Verify suburb data
A8: Boundaries Table
A9: Type | B9: Description
A10: Manual | B10: Editable input cells in yellow
A11: Automatic | B11: Calculated outputs

Sheet Settings
A1: Parameter | B1: Value | C1: Notes
A2: Say in the decision: Mum | B2: 1
A3: Say in the decision: Dad | B3: 1
A4: Say in the decision: Me | B4: 1
A5: Max D (Essential) answers per person | B5: 2
A6: Purchase costs allowance (% of price) | B6: 0.06 | C6: (provisional estimate, not SRO calculation)
A7: Forced-choice override margin | B7: 0.02
A9: Priority Rating Scale | B9: Level | C9: Score
A10: A | B10: Level 1, Not needed | C10: 0
A11: B | B11: Level 2, Nice to have | C11: 1
A12: C | B12: Level 3, Important | C12: 2
A13: D | B13: Level 4, Essential | C13: 4
A15: Draft Baseline Weights | B15: Weight
A16: Q15.1 Nature | B16: 0.18
A17: Q15.2 Near family in GW | B17: 0
A18: Q15.3 Indian community | B18: 0.18
A19: Q15.4 Beach | B19: 0.1
A20: Q15.5 Hospital | B20: 0.15
A21: Q15.6 Train/bus | B21: 0.15
A22: Q15.7 Shops/doctor | B22: 0.09
A23: Q15.8 Village character | B23: 0.07
A24: Q15.9 Price | B24: 0.08
A25: Q15.10 Easy city trip | B25: 0

Sheet RawResponses
A1: Timestamp | B1: [Q0] Whose answers are these? | C1: [Q1] | D1: [Q2] | E1: [Q3] Total budget | F1: [Q4] Max drive to GW | G1: [Q4b] Max drive to GW (if D) | H1: [Q5] Max drive to ED | I1: [Q6] Stairs | J1: [Q7] Garden | K1: [Q7a] Living arrangement | L1: [Q7b] Home size | M1: [Q8] | N1: [Q9] | O1: [Q10] | P1: [Q11] | Q1: [Q12] | R1: [Q13] | S1: [Q13b] | T1: [Q13c] | U1: [Q14] | V1: [Q15.1] Nature | W1: [Q15.2] Near family in GW | X1: [Q15.3] Indian community | Y1: [Q15.4] Beach | Z1: [Q15.5] Hospital | AA1: [Q15.6] Train/bus | AB1: [Q15.7] Shops/doctor | AC1: [Q15.8] Village character | AD1: [Q15.9] Price | AE1: [Q15.10] Easy city trip | AF1: [Q15 Notes] | AG1: [Q16] | AH1: [Q17] | AI1: [Q18] | AJ1: [Q19] | AK1: [Q20] | AL1: [Q21] | AM1: [Gap-form notes]
A2: 0.375 | B2: Dad | E2: 1000000 | F2: C - 35m | H2: C - 30m | I2: B - Some stairs | J2: B - Small garden | O2: Nature | P2: Village character | Q2: Shops & doctor | V2: C | W2: C | X2: C | Y2: C | Z2: C | AA2: C | AB2: C | AC2: C | AD2: D | AE2: D
A3: 0.38541667 | B3: Me | F3: B - 25m | H3: B - 20m | I3: A - None | J3: C - Courtyard | O3: Nature | P3: Village character | Q3: Shops & doctor | V3: D | W3: D | X3: C | Y3: C | Z3: C | AA3: C | AB3: C | AC3: C | AD3: C | AE3: C
A4: 0.39583333 | B4: Mum | E4: 1250000 | F4: B - 25m | H4: B - 20m | I4: A - None at all (Single-level only) | J4: C - Courtyard | K4: D - Self-contained space | O4: Near family in GW | P4: Village character | Q4: Shops & doctor | V4: D | W4: D | X4: D | Y4: C | Z4: C | AA4: C | AB4: C | AC4: C | AD4: C | AE4: C
A5: 0.40625 | B5: Dad | E5: 1500000 | F5: D - 45 min or more | G5: 75 | H5: D - no limit | I5: C - Doesn't matter | J5: E - Depends on Garden | O5: Near family in GW | P5: Village character | Q5: Shops & doctor | V5: D | W5: D | X5: C | Y5: C | Z5: C | AA5: C | AB5: C | AC5: C | AD5: C | AE5: C
A6: 46322.083 | B6: Dad | C6: A — Green views and quiet | D6: D — Looking after the house and land | E6: 1500000 | F6: D - 45 min or more | G6: 75 | H6: D - no limit | I6: C - Doesn't matter | J6: E - Depends on Garden | K6: A — Yes, living together | L6: E — Not decided / depends (see notes) | M6: C — Hills and forest all around | N6: B — Indian groceries and restaurants | O6: Near family in GW | P6: Village character | Q6: Shops & doctor | S6: A — Scenic country or coastal town, 60–90 min from family | T6: A — Inland forest, hills and gardens | U6: A — Stay put and rely on taxis or family | V6: D | W6: D | X6: C | Y6: C | Z6: C | AA6: C | AB6: C | AC6: C | AD6: C | AE6: C | AM6: Merged: row 5 + gap form (Claude artifact) 2026-10-27T02:00:03Z UTC. Notes: Q3–Q7b: ideally D, or min 3 bedrooms
A7: 46322.085 | B7: Mum | C7: A — Green views and quiet | D7: E — None of these / depends (see notes) | E7: 1250000 | F7: B - 25m | H7: B - 20m | I7: A - None at all (Single-level only) | J7: C - Courtyard | K7: A — Yes, living together | L7: E — Not decided / depends (see notes) | M7: A — A green outlook from the house | N7: A — A church or place of worship nearby | O7: Near family in GW | P7: Village character | Q7: Shops & doctor | S7: B — Leafy metropolitan suburb within 35 min of family | T7: B — Coastal or bay town with greenery and water walks | U7: A — Stay put and rely on taxis or family | V7: D | W7: D | X7: D | Y7: C | Z7: C | AA7: C | AB7: C | AC7: C | AD7: C | AE7: C | AM7: Merged: row 4 + gap form (Claude artifact) 2026-10-27T02:02:10Z UTC. Notes: Q1–Q2: B, D, i actually never wanted to live here, it was too remote and cut off. | Q3–Q7b: 3+ bedrooms, but ideally D
A8: 46322.087 | B8: Me | C8: B — Being near the beach | D8: B — Being far from family | F8: B - 25m | H8: B - 20m | I8: A - None | J8: C - Courtyard | K8: A — Yes, living together | L8: D — A self-contained space (granny flat or separate unit) | M8: E — None of these / depends (see notes) | N8: D — Friendly neighbours of any background | O8: Nature | P8: Village character | Q8: Shops & doctor | S8: A — Scenic country or coastal town, 60–90 min from family | T8: B — Coastal or bay town with greenery and water walks | U8: C — Take the train or bus to family and the hospital | V8: D | W8: D | X8: C | Y8: C | Z8: C | AA8: C | AB8: C | AC8: C | AD8: C | AE8: C | AM8: Merged: row 3 + gap form (Claude artifact) 2026-10-27T02:05:04Z UTC. Notes: Q8–Q9: When you picture nature near your new home | Q14: When I picture nature near new home, its a scenic viewpoint like from arthurs seat, of greenery and coast

Sheet CleanedAnswers
A1: Person | B1: Latest Row | C1: Q15 Essential Count
A2: Mum | B2: =IFERROR(LOOKUP(2,1/(RawResponses!$B$2:$B$500="Mum"),ROW(RawResponses!$B$2:$B$500)),"") | C2: {=IF(COUNTIF(INDEX(RawResponses!$A:$AL, B2, 22):INDEX(RawResponses!$A:$AL, B2, 31), "D")>Settings!$B$5, "Too many D's ("&COUNTIF(INDEX(RawResponses!$A:$AL, B2, 22):INDEX(RawResponses!$A:$AL, B2, 31), "D")&")", "OK ("&COUNTIF(INDEX(RawResponses!$A:$AL, B2, 22):INDEX(RawResponses!$A:$AL, B2, 31), "D")&")")}
A3: Dad | B3: =IFERROR(LOOKUP(2,1/(RawResponses!$B$2:$B$500="Dad"),ROW(RawResponses!$B$2:$B$500)),"") | C3: {=IF(COUNTIF(INDEX(RawResponses!$A:$AL, B3, 22):INDEX(RawResponses!$A:$AL, B3, 31), "D")>Settings!$B$5, "Too many D's ("&COUNTIF(INDEX(RawResponses!$A:$AL, B3, 22):INDEX(RawResponses!$A:$AL, B3, 31), "D")&")", "OK ("&COUNTIF(INDEX(RawResponses!$A:$AL, B3, 22):INDEX(RawResponses!$A:$AL, B3, 31), "D")&")")}
A4: Me | B4: =IFERROR(LOOKUP(2,1/(RawResponses!$B$2:$B$500="Me"),ROW(RawResponses!$B$2:$B$500)),"") | C4: {=IF(COUNTIF(INDEX(RawResponses!$A:$AL, B4, 22):INDEX(RawResponses!$A:$AL, B4, 31), "D")>Settings!$B$5, "Too many D's ("&COUNTIF(INDEX(RawResponses!$A:$AL, B4, 22):INDEX(RawResponses!$A:$AL, B4, 31), "D")&")", "OK ("&COUNTIF(INDEX(RawResponses!$A:$AL, B4, 22):INDEX(RawResponses!$A:$AL, B4, 31), "D")&")")}
A6: Question ID | B6: Mum Answer | C6: Dad Answer | D6: Me Answer | E6: Mum Code | F6: Dad Code | G6: Me Code
A7: [Q3] Total budget | B7: {=INDEX(RawResponses!$A:$AL, $B$2, MATCH($A7&"*", RawResponses!$A$1:$AL$1, 0))} | C7: {=INDEX(RawResponses!$A:$AL, $B$3, MATCH($A7&"*", RawResponses!$A$1:$AL$1, 0))} | D7: =INDEX(RawResponses!$A:$AL, $B$4, MATCH($A7&"*", RawResponses!$A$1:$AL$1, 0)) | E7: =LEFT(B7, 1) | F7: =LEFT(C7, 1) | G7: =LEFT(D7, 1)
A8: [Q4] Max drive to GW | B8: {=INDEX(RawResponses!$A:$AL, $B$2, MATCH($A8&"*", RawResponses!$A$1:$AL$1, 0))} | C8: {=INDEX(RawResponses!$A:$AL, $B$3, MATCH($A8&"*", RawResponses!$A$1:$AL$1, 0))} | D8: {=INDEX(RawResponses!$A:$AL, $B$4, MATCH($A8&"*", RawResponses!$A$1:$AL$1, 0))} | E8: =LEFT(B8, 1) | F8: =LEFT(C8, 1) | G8: =LEFT(D8, 1)
A9: [Q4b] Max drive to GW (if D) | B9: =INDEX(RawResponses!$A:$AL, $B$2, MATCH($A9&"*", RawResponses!$A$1:$AL$1, 0)) | C9: {=INDEX(RawResponses!$A:$AL, $B$3, MATCH($A9&"*", RawResponses!$A$1:$AL$1, 0))} | D9: =INDEX(RawResponses!$A:$AL, $B$4, MATCH($A9&"*", RawResponses!$A$1:$AL$1, 0)) | E9: =IF(B9="","",B9) | F9: =IF(C9="","",C9) | G9: =IF(D9="","",D9)
A10: [Q5] Max drive to ED | B10: {=INDEX(RawResponses!$A:$AL, $B$2, MATCH($A10&"*", RawResponses!$A$1:$AL$1, 0))} | C10: {=INDEX(RawResponses!$A:$AL, $B$3, MATCH($A10&"*", RawResponses!$A$1:$AL$1, 0))} | D10: {=INDEX(RawResponses!$A:$AL, $B$4, MATCH($A10&"*", RawResponses!$A$1:$AL$1, 0))} | E10: =LEFT(B10, 1) | F10: =LEFT(C10, 1) | G10: =LEFT(D10, 1)
A11: [Q6] Stairs | B11: {=INDEX(RawResponses!$A:$AL, $B$2, MATCH($A11&"*", RawResponses!$A$1:$AL$1, 0))} | C11: {=INDEX(RawResponses!$A:$AL, $B$3, MATCH($A11&"*", RawResponses!$A$1:$AL$1, 0))} | D11: {=INDEX(RawResponses!$A:$AL, $B$4, MATCH($A11&"*", RawResponses!$A$1:$AL$1, 0))} | E11: =LEFT(B11, 1) | F11: =LEFT(C11, 1) | G11: =LEFT(D11, 1)
A12: [Q7] Garden | B12: {=INDEX(RawResponses!$A:$AL, $B$2, MATCH($A12&"*", RawResponses!$A$1:$AL$1, 0))} | C12: {=INDEX(RawResponses!$A:$AL, $B$3, MATCH($A12&"*", RawResponses!$A$1:$AL$1, 0))} | D12: {=INDEX(RawResponses!$A:$AL, $B$4, MATCH($A12&"*", RawResponses!$A$1:$AL$1, 0))} | E12: =LEFT(B12, 1) | F12: =LEFT(C12, 1) | G12: =LEFT(D12, 1)
A13: [Q7a] Living arrangement | B13: {=INDEX(RawResponses!$A:$AL, $B$2, MATCH($A13&"*", RawResponses!$A$1:$AL$1, 0))} | C13: =INDEX(RawResponses!$A:$AL, $B$3, MATCH($A13&"*", RawResponses!$A$1:$AL$1, 0)) | D13: =INDEX(RawResponses!$A:$AL, $B$4, MATCH($A13&"*", RawResponses!$A$1:$AL$1, 0)) | E13: =LEFT(B13, 1) | F13: =LEFT(C13, 1) | G13: =LEFT(D13, 1)
A14: [Q7b] Home size | B14: =INDEX(RawResponses!$A:$AL, $B$2, MATCH($A14&"*", RawResponses!$A$1:$AL$1, 0)) | C14: =INDEX(RawResponses!$A:$AL, $B$3, MATCH($A14&"*", RawResponses!$A$1:$AL$1, 0)) | D14: =INDEX(RawResponses!$A:$AL, $B$4, MATCH($A14&"*", RawResponses!$A$1:$AL$1, 0)) | E14: =LEFT(B14, 1) | F14: =LEFT(C14, 1) | G14: =LEFT(D14, 1)
A15: [Q10] | B15: {=INDEX(RawResponses!$A:$AL, $B$2, MATCH($A15&"*", RawResponses!$A$1:$AL$1, 0))} | C15: {=INDEX(RawResponses!$A:$AL, $B$3, MATCH($A15&"*", RawResponses!$A$1:$AL$1, 0))} | D15: {=INDEX(RawResponses!$A:$AL, $B$4, MATCH($A15&"*", RawResponses!$A$1:$AL$1, 0))} | E15: =LEFT(B15, 1) | F15: =LEFT(C15, 1) | G15: =LEFT(D15, 1)
A16: [Q11] | B16: {=INDEX(RawResponses!$A:$AL, $B$2, MATCH($A16&"*", RawResponses!$A$1:$AL$1, 0))} | C16: {=INDEX(RawResponses!$A:$AL, $B$3, MATCH($A16&"*", RawResponses!$A$1:$AL$1, 0))} | D16: {=INDEX(RawResponses!$A:$AL, $B$4, MATCH($A16&"*", RawResponses!$A$1:$AL$1, 0))} | E16: =LEFT(B16, 1) | F16: =LEFT(C16, 1) | G16: =LEFT(D16, 1)
A17: [Q12] | B17: {=INDEX(RawResponses!$A:$AL, $B$2, MATCH($A17&"*", RawResponses!$A$1:$AL$1, 0))} | C17: {=INDEX(RawResponses!$A:$AL, $B$3, MATCH($A17&"*", RawResponses!$A$1:$AL$1, 0))} | D17: {=INDEX(RawResponses!$A:$AL, $B$4, MATCH($A17&"*", RawResponses!$A$1:$AL$1, 0))} | E17: =LEFT(B17, 1) | F17: =LEFT(C17, 1) | G17: =LEFT(D17, 1)
A18: [Q13] | B18: =INDEX(RawResponses!$A:$AL, $B$2, MATCH($A18&"*", RawResponses!$A$1:$AL$1, 0)) | C18: =INDEX(RawResponses!$A:$AL, $B$3, MATCH($A18&"*", RawResponses!$A$1:$AL$1, 0)) | D18: =INDEX(RawResponses!$A:$AL, $B$4, MATCH($A18&"*", RawResponses!$A$1:$AL$1, 0)) | E18: =LEFT(B18, 1) | F18: =LEFT(C18, 1) | G18: =LEFT(D18, 1)
A19: [Q15.1] Nature | B19: {=INDEX(RawResponses!$A:$AL, $B$2, MATCH($A19&"*", RawResponses!$A$1:$AL$1, 0))} | C19: {=INDEX(RawResponses!$A:$AL, $B$3, MATCH($A19&"*", RawResponses!$A$1:$AL$1, 0))} | D19: {=INDEX(RawResponses!$A:$AL, $B$4, MATCH($A19&"*", RawResponses!$A$1:$AL$1, 0))} | E19: =LEFT(B19, 1) | F19: =LEFT(C19, 1) | G19: =LEFT(D19, 1)
A20: [Q15.2] Near family in GW | B20: {=INDEX(RawResponses!$A:$AL, $B$2, MATCH($A20&"*", RawResponses!$A$1:$AL$1, 0))} | C20: {=INDEX(RawResponses!$A:$AL, $B$3, MATCH($A20&"*", RawResponses!$A$1:$AL$1, 0))} | D20: {=INDEX(RawResponses!$A:$AL, $B$4, MATCH($A20&"*", RawResponses!$A$1:$AL$1, 0))} | E20: =LEFT(B20, 1) | F20: =LEFT(C20, 1) | G20: =LEFT(D20, 1)
A21: [Q15.3] Indian community | B21: {=INDEX(RawResponses!$A:$AL, $B$2, MATCH($A21&"*", RawResponses!$A$1:$AL$1, 0))} | C21: {=INDEX(RawResponses!$A:$AL, $B$3, MATCH($A21&"*", RawResponses!$A$1:$AL$1, 0))} | D21: {=INDEX(RawResponses!$A:$AL, $B$4, MATCH($A21&"*", RawResponses!$A$1:$AL$1, 0))} | E21: =LEFT(B21, 1) | F21: =LEFT(C21, 1) | G21: =LEFT(D21, 1)
A22: [Q15.4] Beach | B22: {=INDEX(RawResponses!$A:$AL, $B$2, MATCH($A22&"*", RawResponses!$A$1:$AL$1, 0))} | C22: {=INDEX(RawResponses!$A:$AL, $B$3, MATCH($A22&"*", RawResponses!$A$1:$AL$1, 0))} | D22: {=INDEX(RawResponses!$A:$AL, $B$4, MATCH($A22&"*", RawResponses!$A$1:$AL$1, 0))} | E22: =LEFT(B22, 1) | F22: =LEFT(C22, 1) | G22: =LEFT(D22, 1)
A23: [Q15.5] Hospital | B23: {=INDEX(RawResponses!$A:$AL, $B$2, MATCH($A23&"*", RawResponses!$A$1:$AL$1, 0))} | C23: {=INDEX(RawResponses!$A:$AL, $B$3, MATCH($A23&"*", RawResponses!$A$1:$AL$1, 0))} | D23: {=INDEX(RawResponses!$A:$AL, $B$4, MATCH($A23&"*", RawResponses!$A$1:$AL$1, 0))} | E23: =LEFT(B23, 1) | F23: =LEFT(C23, 1) | G23: =LEFT(D23, 1)
A24: [Q15.6] Train/bus | B24: {=INDEX(RawResponses!$A:$AL, $B$2, MATCH($A24&"*", RawResponses!$A$1:$AL$1, 0))} | C24: {=INDEX(RawResponses!$A:$AL, $B$3, MATCH($A24&"*", RawResponses!$A$1:$AL$1, 0))} | D24: {=INDEX(RawResponses!$A:$AL, $B$4, MATCH($A24&"*", RawResponses!$A$1:$AL$1, 0))} | E24: =LEFT(B24, 1) | F24: =LEFT(C24, 1) | G24: =LEFT(D24, 1)
A25: [Q15.7] Shops/doctor | B25: {=INDEX(RawResponses!$A:$AL, $B$2, MATCH($A25&"*", RawResponses!$A$1:$AL$1, 0))} | C25: {=INDEX(RawResponses!$A:$AL, $B$3, MATCH($A25&"*", RawResponses!$A$1:$AL$1, 0))} | D25: {=INDEX(RawResponses!$A:$AL, $B$4, MATCH($A25&"*", RawResponses!$A$1:$AL$1, 0))} | E25: =LEFT(B25, 1) | F25: =LEFT(C25, 1) | G25: =LEFT(D25, 1)
A26: [Q15.8] Village character | B26: {=INDEX(RawResponses!$A:$AL, $B$2, MATCH($A26&"*", RawResponses!$A$1:$AL$1, 0))} | C26: {=INDEX(RawResponses!$A:$AL, $B$3, MATCH($A26&"*", RawResponses!$A$1:$AL$1, 0))} | D26: {=INDEX(RawResponses!$A:$AL, $B$4, MATCH($A26&"*", RawResponses!$A$1:$AL$1, 0))} | E26: =LEFT(B26, 1) | F26: =LEFT(C26, 1) | G26: =LEFT(D26, 1)
A27: [Q15.9] Price | B27: {=INDEX(RawResponses!$A:$AL, $B$2, MATCH($A27&"*", RawResponses!$A$1:$AL$1, 0))} | C27: {=INDEX(RawResponses!$A:$AL, $B$3, MATCH($A27&"*", RawResponses!$A$1:$AL$1, 0))} | D27: {=INDEX(RawResponses!$A:$AL, $B$4, MATCH($A27&"*", RawResponses!$A$1:$AL$1, 0))} | E27: =LEFT(B27, 1) | F27: =LEFT(C27, 1) | G27: =LEFT(D27, 1)
A28: [Q15.10] Easy city trip | B28: {=INDEX(RawResponses!$A:$AL, $B$2, MATCH($A28&"*", RawResponses!$A$1:$AL$1, 0))} | C28: {=INDEX(RawResponses!$A:$AL, $B$3, MATCH($A28&"*", RawResponses!$A$1:$AL$1, 0))} | D28: {=INDEX(RawResponses!$A:$AL, $B$4, MATCH($A28&"*", RawResponses!$A$1:$AL$1, 0))} | E28: =LEFT(B28, 1) | F28: =LEFT(C28, 1) | G28: =LEFT(D28, 1)
A30: Context answers (shown for discussion; not weighted)
A31: Question ID | B31: Mum Answer | C31: Dad Answer | D31: Me Answer | E31: Mum Code | F31: Dad Code | G31: Me Code
A32: [Q1] | B32: =IFERROR(IF(INDEX(RawResponses!$A:$AM,$B$2,MATCH($A32&"*",RawResponses!$A$1:$AM$1,0))="","",INDEX(RawResponses!$A:$AM,$B$2,MATCH($A32&"*",RawResponses!$A$1:$AM$1,0))),"") | C32: =IFERROR(IF(INDEX(RawResponses!$A:$AM,$B$3,MATCH($A32&"*",RawResponses!$A$1:$AM$1,0))="","",INDEX(RawResponses!$A:$AM,$B$3,MATCH($A32&"*",RawResponses!$A$1:$AM$1,0))),"") | D32: =IFERROR(IF(INDEX(RawResponses!$A:$AM,$B$4,MATCH($A32&"*",RawResponses!$A$1:$AM$1,0))="","",INDEX(RawResponses!$A:$AM,$B$4,MATCH($A32&"*",RawResponses!$A$1:$AM$1,0))),"") | E32: =LEFT(B32,1) | F32: =LEFT(C32,1) | G32: =LEFT(D32,1)
A33: [Q2] | B33: =IFERROR(IF(INDEX(RawResponses!$A:$AM,$B$2,MATCH($A33&"*",RawResponses!$A$1:$AM$1,0))="","",INDEX(RawResponses!$A:$AM,$B$2,MATCH($A33&"*",RawResponses!$A$1:$AM$1,0))),"") | C33: =IFERROR(IF(INDEX(RawResponses!$A:$AM,$B$3,MATCH($A33&"*",RawResponses!$A$1:$AM$1,0))="","",INDEX(RawResponses!$A:$AM,$B$3,MATCH($A33&"*",RawResponses!$A$1:$AM$1,0))),"") | D33: =IFERROR(IF(INDEX(RawResponses!$A:$AM,$B$4,MATCH($A33&"*",RawResponses!$A$1:$AM$1,0))="","",INDEX(RawResponses!$A:$AM,$B$4,MATCH($A33&"*",RawResponses!$A$1:$AM$1,0))),"") | E33: =LEFT(B33,1) | F33: =LEFT(C33,1) | G33: =LEFT(D33,1)
A34: [Q8] | B34: =IFERROR(IF(INDEX(RawResponses!$A:$AM,$B$2,MATCH($A34&"*",RawResponses!$A$1:$AM$1,0))="","",INDEX(RawResponses!$A:$AM,$B$2,MATCH($A34&"*",RawResponses!$A$1:$AM$1,0))),"") | C34: =IFERROR(IF(INDEX(RawResponses!$A:$AM,$B$3,MATCH($A34&"*",RawResponses!$A$1:$AM$1,0))="","",INDEX(RawResponses!$A:$AM,$B$3,MATCH($A34&"*",RawResponses!$A$1:$AM$1,0))),"") | D34: =IFERROR(IF(INDEX(RawResponses!$A:$AM,$B$4,MATCH($A34&"*",RawResponses!$A$1:$AM$1,0))="","",INDEX(RawResponses!$A:$AM,$B$4,MATCH($A34&"*",RawResponses!$A$1:$AM$1,0))),"") | E34: =LEFT(B34,1) | F34: =LEFT(C34,1) | G34: =LEFT(D34,1)
A35: [Q9] | B35: =IFERROR(IF(INDEX(RawResponses!$A:$AM,$B$2,MATCH($A35&"*",RawResponses!$A$1:$AM$1,0))="","",INDEX(RawResponses!$A:$AM,$B$2,MATCH($A35&"*",RawResponses!$A$1:$AM$1,0))),"") | C35: =IFERROR(IF(INDEX(RawResponses!$A:$AM,$B$3,MATCH($A35&"*",RawResponses!$A$1:$AM$1,0))="","",INDEX(RawResponses!$A:$AM,$B$3,MATCH($A35&"*",RawResponses!$A$1:$AM$1,0))),"") | D35: =IFERROR(IF(INDEX(RawResponses!$A:$AM,$B$4,MATCH($A35&"*",RawResponses!$A$1:$AM$1,0))="","",INDEX(RawResponses!$A:$AM,$B$4,MATCH($A35&"*",RawResponses!$A$1:$AM$1,0))),"") | E35: =LEFT(B35,1) | F35: =LEFT(C35,1) | G35: =LEFT(D35,1)
A36: [Q13b] | B36: =IFERROR(IF(INDEX(RawResponses!$A:$AM,$B$2,MATCH($A36&"*",RawResponses!$A$1:$AM$1,0))="","",INDEX(RawResponses!$A:$AM,$B$2,MATCH($A36&"*",RawResponses!$A$1:$AM$1,0))),"") | C36: =IFERROR(IF(INDEX(RawResponses!$A:$AM,$B$3,MATCH($A36&"*",RawResponses!$A$1:$AM$1,0))="","",INDEX(RawResponses!$A:$AM,$B$3,MATCH($A36&"*",RawResponses!$A$1:$AM$1,0))),"") | D36: =IFERROR(IF(INDEX(RawResponses!$A:$AM,$B$4,MATCH($A36&"*",RawResponses!$A$1:$AM$1,0))="","",INDEX(RawResponses!$A:$AM,$B$4,MATCH($A36&"*",RawResponses!$A$1:$AM$1,0))),"") | E36: =LEFT(B36,1) | F36: =LEFT(C36,1) | G36: =LEFT(D36,1)
A37: [Q13c] | B37: =IFERROR(IF(INDEX(RawResponses!$A:$AM,$B$2,MATCH($A37&"*",RawResponses!$A$1:$AM$1,0))="","",INDEX(RawResponses!$A:$AM,$B$2,MATCH($A37&"*",RawResponses!$A$1:$AM$1,0))),"") | C37: =IFERROR(IF(INDEX(RawResponses!$A:$AM,$B$3,MATCH($A37&"*",RawResponses!$A$1:$AM$1,0))="","",INDEX(RawResponses!$A:$AM,$B$3,MATCH($A37&"*",RawResponses!$A$1:$AM$1,0))),"") | D37: =IFERROR(IF(INDEX(RawResponses!$A:$AM,$B$4,MATCH($A37&"*",RawResponses!$A$1:$AM$1,0))="","",INDEX(RawResponses!$A:$AM,$B$4,MATCH($A37&"*",RawResponses!$A$1:$AM$1,0))),"") | E37: =LEFT(B37,1) | F37: =LEFT(C37,1) | G37: =LEFT(D37,1)
A38: [Q14] | B38: =IFERROR(IF(INDEX(RawResponses!$A:$AM,$B$2,MATCH($A38&"*",RawResponses!$A$1:$AM$1,0))="","",INDEX(RawResponses!$A:$AM,$B$2,MATCH($A38&"*",RawResponses!$A$1:$AM$1,0))),"") | C38: =IFERROR(IF(INDEX(RawResponses!$A:$AM,$B$3,MATCH($A38&"*",RawResponses!$A$1:$AM$1,0))="","",INDEX(RawResponses!$A:$AM,$B$3,MATCH($A38&"*",RawResponses!$A$1:$AM$1,0))),"") | D38: =IFERROR(IF(INDEX(RawResponses!$A:$AM,$B$4,MATCH($A38&"*",RawResponses!$A$1:$AM$1,0))="","",INDEX(RawResponses!$A:$AM,$B$4,MATCH($A38&"*",RawResponses!$A$1:$AM$1,0))),"") | E38: =LEFT(B38,1) | F38: =LEFT(C38,1) | G38: =LEFT(D38,1)
A39: [Gap-form notes] | B39: =IFERROR(IF(INDEX(RawResponses!$A:$AM,$B$2,MATCH($A39&"*",RawResponses!$A$1:$AM$1,0))="","",INDEX(RawResponses!$A:$AM,$B$2,MATCH($A39&"*",RawResponses!$A$1:$AM$1,0))),"") | C39: =IFERROR(IF(INDEX(RawResponses!$A:$AM,$B$3,MATCH($A39&"*",RawResponses!$A$1:$AM$1,0))="","",INDEX(RawResponses!$A:$AM,$B$3,MATCH($A39&"*",RawResponses!$A$1:$AM$1,0))),"") | D39: =IFERROR(IF(INDEX(RawResponses!$A:$AM,$B$4,MATCH($A39&"*",RawResponses!$A$1:$AM$1,0))="","",INDEX(RawResponses!$A:$AM,$B$4,MATCH($A39&"*",RawResponses!$A$1:$AM$1,0))),"")

Sheet Filters
A1: Filter | B1: Strictest Constraint | C1: Notes | D1: Survey-derived value (reference only)
A2: Q3 Total budget | B2: 1500000 | C2: Confirmed family decision 27 Oct 2026: budget cap set to $1,500,000 maximum purchase price (excluding transaction & moving costs). Replaces survey strictest of $1,250,000. | D2: 1250000
A3: Total acquisition ceiling (Price + 6% costs) | B3: =B2 * (1 + Settings!B6) | C3: Total outlay cap ($1,590,000) including 6% stamp duty/conveyancing/moving allowance on $1,500,000 purchase price.
A4: Q4/Q4b Max drive to GW | B4: 90 | C4: Family decision 26 Oct 2026: hard max 90 min (60 min preferred); a train option is now preferred, not required (see row 9, changed by NJD, family to confirm). Replaces survey strictest of 25 min (Mum/Me); Dad said up to 75. | D4: =MIN(IF(CleanedAnswers!E8="D",IF(ISNUMBER(CleanedAnswers!B9),CleanedAnswers!B9,999),IFERROR(CHOOSE(MATCH(CleanedAnswers!E8,{"A","B","C"},0),15,25,35),999)),IF(CleanedAnswers!F8="D",IF(ISNUMBER(CleanedAnswers!C9),CleanedAnswers!C9,999),IFERROR(CHOOSE(MATCH(CleanedAnswers!F8,{"A","B","C"},0),15,25,35),999)),IF(CleanedAnswers!G8="D",IF(ISNUMBER(CleanedAnswers!D9),CleanedAnswers!D9,999),IFERROR(CHOOSE(MATCH(CleanedAnswers!G8,{"A","B","C"},0),15,25,35),999)))
A5: Q5 Max drive to ED | B5: 90 | C5: Family decision 26 Oct 2026: hard cap 90 min, and ED time is also scored (SuburbScorecard column O). Replaces survey strictest of 20 min (Mum/Me); Dad said no limit.
A6: Q6 Stairs | B6: Stairs allowed (single-level not required) | C6: CORRECTED 27 Oct 2026 by NJD: stairs are allowed, so this is no longer a hard filter. Previous value was the survey strictest answer (formula kept in D6). | D6: =IF(COUNTIF(CleanedAnswers!E11:G11, "A")>0, "A — None at all (Single-level only)", "Check")
A7: Q7a/Q7b Living arrangement | B7: Needs discussion (Living arrangement undecided): D — Self-contained space
A8: Q7 Garden | B8: Needs discussion (Depends — see notes)
A9: Train option | B9: Preferred, not required (scored via SuburbScorecard column S) | C9: CHANGED 26 Oct 2026 by NJD from 'Required (a train station in or at the edge of the suburb)', which had been recorded as a family decision earlier that day. Family to confirm. Reason: a hard rule removes bush and coastal areas that have not been viewed. Column AB on SuburbScorecard: Yes / No.
A10: Drive-time basis | B10: Google Maps drive time, 'leave now' typical traffic, looked up 26 Oct 2026 | C10: Not tested at peak hour. J = to Glen Waverley (suburb centre). K = to the nearest 24-hr public ED listed in SuburbScorecard column AD. Train Yes/No is from recall and sheet notes, not checked against timetables.

Sheet PriorityWeights
A1: Question | B1: Mum Code | C1: Dad Code | D1: Me Code | E1: Mum Score | F1: Dad Score | G1: Me Score | H1: Mum Norm | I1: Dad Norm | J1: Me Norm | K1: Combined Weight
A2: Nature | B2: =CleanedAnswers!E19 | C2: =CleanedAnswers!F19 | D2: =CleanedAnswers!G19 | E2: =VLOOKUP(B2, Settings!$A$10:$C$13, 3, FALSE()) | F2: =VLOOKUP(C2, Settings!$A$10:$C$13, 3, FALSE()) | G2: =VLOOKUP(D2, Settings!$A$10:$C$13, 3, FALSE()) | H2: =E2/SUM(E$2:E$11) | I2: =F2/SUM(F$2:F$11) | J2: =G2/SUM(G$2:G$11) | K2: =(H2*Settings!$B$2 + I2*Settings!$B$3 + J2*Settings!$B$4)/(Settings!$B$2+Settings!$B$3+Settings!$B$4)
A3: Near family in GW | B3: =CleanedAnswers!E20 | C3: =CleanedAnswers!F20 | D3: =CleanedAnswers!G20 | E3: =VLOOKUP(B3, Settings!$A$10:$C$13, 3, FALSE()) | F3: =VLOOKUP(C3, Settings!$A$10:$C$13, 3, FALSE()) | G3: =VLOOKUP(D3, Settings!$A$10:$C$13, 3, FALSE()) | H3: =E3/SUM(E$2:E$11) | I3: =F3/SUM(F$2:F$11) | J3: =G3/SUM(G$2:G$11) | K3: =(H3*Settings!$B$2 + I3*Settings!$B$3 + J3*Settings!$B$4)/(Settings!$B$2+Settings!$B$3+Settings!$B$4)
A4: Indian community | B4: =CleanedAnswers!E21 | C4: =CleanedAnswers!F21 | D4: =CleanedAnswers!G21 | E4: =VLOOKUP(B4, Settings!$A$10:$C$13, 3, FALSE()) | F4: =VLOOKUP(C4, Settings!$A$10:$C$13, 3, FALSE()) | G4: =VLOOKUP(D4, Settings!$A$10:$C$13, 3, FALSE()) | H4: =E4/SUM(E$2:E$11) | I4: =F4/SUM(F$2:F$11) | J4: =G4/SUM(G$2:G$11) | K4: =(H4*Settings!$B$2 + I4*Settings!$B$3 + J4*Settings!$B$4)/(Settings!$B$2+Settings!$B$3+Settings!$B$4)
A5: Beach | B5: =CleanedAnswers!E22 | C5: =CleanedAnswers!F22 | D5: =CleanedAnswers!G22 | E5: =VLOOKUP(B5, Settings!$A$10:$C$13, 3, FALSE()) | F5: =VLOOKUP(C5, Settings!$A$10:$C$13, 3, FALSE()) | G5: =VLOOKUP(D5, Settings!$A$10:$C$13, 3, FALSE()) | H5: =E5/SUM(E$2:E$11) | I5: =F5/SUM(F$2:F$11) | J5: =G5/SUM(G$2:G$11) | K5: =(H5*Settings!$B$2 + I5*Settings!$B$3 + J5*Settings!$B$4)/(Settings!$B$2+Settings!$B$3+Settings!$B$4)
A6: Hospital | B6: =CleanedAnswers!E23 | C6: =CleanedAnswers!F23 | D6: =CleanedAnswers!G23 | E6: =VLOOKUP(B6, Settings!$A$10:$C$13, 3, FALSE()) | F6: =VLOOKUP(C6, Settings!$A$10:$C$13, 3, FALSE()) | G6: =VLOOKUP(D6, Settings!$A$10:$C$13, 3, FALSE()) | H6: =E6/SUM(E$2:E$11) | I6: =F6/SUM(F$2:F$11) | J6: =G6/SUM(G$2:G$11) | K6: =(H6*Settings!$B$2 + I6*Settings!$B$3 + J6*Settings!$B$4)/(Settings!$B$2+Settings!$B$3+Settings!$B$4)
A7: Train/bus | B7: =CleanedAnswers!E24 | C7: =CleanedAnswers!F24 | D7: =CleanedAnswers!G24 | E7: =VLOOKUP(B7, Settings!$A$10:$C$13, 3, FALSE()) | F7: =VLOOKUP(C7, Settings!$A$10:$C$13, 3, FALSE()) | G7: =VLOOKUP(D7, Settings!$A$10:$C$13, 3, FALSE()) | H7: =E7/SUM(E$2:E$11) | I7: =F7/SUM(F$2:F$11) | J7: =G7/SUM(G$2:G$11) | K7: =(H7*Settings!$B$2 + I7*Settings!$B$3 + J7*Settings!$B$4)/(Settings!$B$2+Settings!$B$3+Settings!$B$4)
A8: Shops/doctor | B8: =CleanedAnswers!E25 | C8: =CleanedAnswers!F25 | D8: =CleanedAnswers!G25 | E8: =VLOOKUP(B8, Settings!$A$10:$C$13, 3, FALSE()) | F8: =VLOOKUP(C8, Settings!$A$10:$C$13, 3, FALSE()) | G8: =VLOOKUP(D8, Settings!$A$10:$C$13, 3, FALSE()) | H8: =E8/SUM(E$2:E$11) | I8: =F8/SUM(F$2:F$11) | J8: =G8/SUM(G$2:G$11) | K8: =(H8*Settings!$B$2 + I8*Settings!$B$3 + J8*Settings!$B$4)/(Settings!$B$2+Settings!$B$3+Settings!$B$4)
A9: Village character | B9: =CleanedAnswers!E26 | C9: =CleanedAnswers!F26 | D9: =CleanedAnswers!G26 | E9: =VLOOKUP(B9, Settings!$A$10:$C$13, 3, FALSE()) | F9: =VLOOKUP(C9, Settings!$A$10:$C$13, 3, FALSE()) | G9: =VLOOKUP(D9, Settings!$A$10:$C$13, 3, FALSE()) | H9: =E9/SUM(E$2:E$11) | I9: =F9/SUM(F$2:F$11) | J9: =G9/SUM(G$2:G$11) | K9: =(H9*Settings!$B$2 + I9*Settings!$B$3 + J9*Settings!$B$4)/(Settings!$B$2+Settings!$B$3+Settings!$B$4)
A10: Price | B10: =CleanedAnswers!E27 | C10: =CleanedAnswers!F27 | D10: =CleanedAnswers!G27 | E10: =VLOOKUP(B10, Settings!$A$10:$C$13, 3, FALSE()) | F10: =VLOOKUP(C10, Settings!$A$10:$C$13, 3, FALSE()) | G10: =VLOOKUP(D10, Settings!$A$10:$C$13, 3, FALSE()) | H10: =E10/SUM(E$2:E$11) | I10: =F10/SUM(F$2:F$11) | J10: =G10/SUM(G$2:G$11) | K10: =(H10*Settings!$B$2 + I10*Settings!$B$3 + J10*Settings!$B$4)/(Settings!$B$2+Settings!$B$3+Settings!$B$4)
A11: Easy city trip | B11: =CleanedAnswers!E28 | C11: =CleanedAnswers!F28 | D11: =CleanedAnswers!G28 | E11: =VLOOKUP(B11, Settings!$A$10:$C$13, 3, FALSE()) | F11: =VLOOKUP(C11, Settings!$A$10:$C$13, 3, FALSE()) | G11: =VLOOKUP(D11, Settings!$A$10:$C$13, 3, FALSE()) | H11: =E11/SUM(E$2:E$11) | I11: =F11/SUM(F$2:F$11) | J11: =G11/SUM(G$2:G$11) | K11: =(H11*Settings!$B$2 + I11*Settings!$B$3 + J11*Settings!$B$4)/(Settings!$B$2+Settings!$B$3+Settings!$B$4)

Sheet ForcedChoiceCorrections
A1: Matchup | B1: Result
A2: Q10 | B2: +7.2% from Nature to Near family in GW
A3: Q12 | B3: +2.6% from Village character to Shops & doctor
A5: Final Normalized Weights | B5: Weight | C5: Forced-choice shift (editable) | D5: Survey weight (PriorityWeights K) | E5: Previous typed weight (pre 27 Oct link)
A6: Near family in GW | B6: =MAX(0,D6+C6)/SUMPRODUCT((D$6:D$15+C$6:C$15>0)*(D$6:D$15+C$6:C$15)) | C6: 0.072 | D6: =PriorityWeights!K3 | E6: 0.153
A7: Nature | B7: =MAX(0,D7+C7)/SUMPRODUCT((D$6:D$15+C$6:C$15>0)*(D$6:D$15+C$6:C$15)) | C7: -0.072 | D7: =PriorityWeights!K2 | E7: 0.133
A8: Hospital | B8: =MAX(0,D8+C8)/SUMPRODUCT((D$6:D$15+C$6:C$15>0)*(D$6:D$15+C$6:C$15)) | C8: 0 | D8: =PriorityWeights!K6 | E8: 0.133
A9: Indian community | B9: =MAX(0,D9+C9)/SUMPRODUCT((D$6:D$15+C$6:C$15>0)*(D$6:D$15+C$6:C$15)) | C9: 0 | D9: =PriorityWeights!K4 | E9: 0.117
A10: Shops & doctor | B10: =MAX(0,D10+C10)/SUMPRODUCT((D$6:D$15+C$6:C$15>0)*(D$6:D$15+C$6:C$15)) | C10: 0.026 | D10: =PriorityWeights!K8 | E10: 0.108
A11: Village character | B11: =MAX(0,D11+C11)/SUMPRODUCT((D$6:D$15+C$6:C$15>0)*(D$6:D$15+C$6:C$15)) | C11: -0.026 | D11: =PriorityWeights!K9 | E11: 0.088
A12: Train/bus | B12: =MAX(0,D12+C12)/SUMPRODUCT((D$6:D$15+C$6:C$15>0)*(D$6:D$15+C$6:C$15)) | C12: 0 | D12: =PriorityWeights!K7 | E12: 0.081
A13: Price | B13: =MAX(0,D13+C13)/SUMPRODUCT((D$6:D$15+C$6:C$15>0)*(D$6:D$15+C$6:C$15)) | C13: 0 | D13: =PriorityWeights!K10 | E13: 0.081
A14: Beach | B14: =MAX(0,D14+C14)/SUMPRODUCT((D$6:D$15+C$6:C$15>0)*(D$6:D$15+C$6:C$15)) | C14: 0 | D14: =PriorityWeights!K5 | E14: 0.061
A15: City trip | B15: =MAX(0,D15+C15)/SUMPRODUCT((D$6:D$15+C$6:C$15>0)*(D$6:D$15+C$6:C$15)) | C15: 0 | D15: =PriorityWeights!K11 | E15: 0.045
A16: Total | B16: =SUM(B6:B15)
A18: Note (27 Oct 2026): B was typed values (kept in E). Now B = survey weight + shift, renormalised. Shifts carried over from rows Q10/Q12 above; they came from the earlier answers and should be recomputed after the round-2 questionnaire.

Sheet SuburbScorecard
A1: Location | B1: Region | C1: Shortlist Status | D1: Parents Inland/Bush Fit (P) | E1: My Coastal-Nature Fit (Y) | F1: Primary Investigation Lens | G1: Published House Price | H1: Price Basis | I1: Price + Est. 6% Costs | J1: Drive to GW (min) | K1: Drive to 24-Hr Public ED (min) | L1: Hard Filter Status | M1: Score: Near family in GW | N1: Score: Nature | O1: Score: Hospital | P1: Score: Indian community | Q1: Score: Shops & doctor | R1: Score: Village character | S1: Score: Train/bus | T1: Score: Price | U1: Score: Beach | V1: Score: City trip | W1: Scores Entered | X1: Weighted Score (0-10) | Y1: Rank (Passing Only) | Z1: Healthcare & ABS Verification Notes | AA1: Legacy import text (frozen 27 Oct 2026; not used by any formula — edit columns A–H and Z instead) | AB1: Train Option (Yes/No) | AC1: Train Station / Basis | AD1: ED Used for Drive Time (K) | AE1: Budget cap — purchase price | AF1: Budget basis | AG1: Price evidence type | AH1: Price evidence date | AI1: Budget result | AJ1: Budget note
A2: Blackburn | B2: East Melbourne | C2: Active Shortlist | D2: Medium (Leafy streets) | E2: Low (Inland) | F2: Leafy daily living vs housing cost | G2: 1600000 | H2: Sale median, rolling 12m (OnTheHouse); unit $820k | I2: {=IF(ISNUMBER(G2:G90), IF(G2:G90>0, G2:G90 * (1 + Settings!$B$6), ""), "")} | J2: 11 | K2: 7 | L2: Active — needs data | O2: =IF(K2="","",ROUND(MAX(0,10*(1-K2/Filters!$B$5)),1)) | W2: =IF(M2="",0,COUNT(M2:V2)) | X2: =IF(W2<10,"",M2*ForcedChoiceCorrections!$B$6+N2*ForcedChoiceCorrections!$B$7+O2*ForcedChoiceCorrections!$B$8+P2*ForcedChoiceCorrections!$B$9+Q2*ForcedChoiceCorrections!$B$10+R2*ForcedChoiceCorrections!$B$11+S2*ForcedChoiceCorrections!$B$12+T2*ForcedChoiceCorrections!$B$13+U2*ForcedChoiceCorrections!$B$14+V2*ForcedChoiceCorrections!$B$15) | Y2: =IF(AND(ISNUMBER(SEARCH("pass",L2)),ISNUMBER(X2)),COUNTIFS(L$2:L$90,"*pass*",X$2:X$90,">"&X2)+1,"") | Z2: ABS 2021: 32.4% overseas-born, 31.6% non-Eng HH. Station/ED journeys unverified. | AA2: 1. Blackburn | East Melbourne | Active Shortlist | P: Medium (Leafy streets) | Y: Low (Inland) | Lens: Leafy daily living vs housing cost | Price: 1600000 | Basis: Sale median, rolling 12m (OnTheHouse); unit $820k | Note: ABS 2021: 32.4% overseas-born, 31.6% non-Eng HH. Station/ED journeys unverified. | AB2: Yes | AC2: Blackburn station, Lilydale line (recall; verify) | AD2: Box Hill Hospital ED | AE2: 1500000 | AF2: Maximum purchase price, excluding transaction and moving costs | AG2: Suburb median | AH2: 26 Oct 2026 | AI2: Needs data | AJ2: House median $1.60M (OnTheHouse) exceeds $1.5M cap, but unit/villa median is $820k. Awaiting documented search for suitable single-level homes/units under $1.5M.
A3: Ringwood | B3: East Melbourne | C3: Active Shortlist | D3: Medium-High (Foothills gateway) | E3: Low (Inland) | F3: Rail, services & access to greener surroundings | G3: 1045000 | H3: Sale median, rolling 12m (OnTheHouse); unit $650k | I3: 1107700 | J3: 12 | K3: 5 | L3: Active — provisional pass | O3: =IF(K3="","",ROUND(MAX(0,10*(1-K3/Filters!$B$5)),1)) | W3: =IF(M3="",0,COUNT(M3:V3)) | X3: =IF(W3<10,"",M3*ForcedChoiceCorrections!$B$6+N3*ForcedChoiceCorrections!$B$7+O3*ForcedChoiceCorrections!$B$8+P3*ForcedChoiceCorrections!$B$9+Q3*ForcedChoiceCorrections!$B$10+R3*ForcedChoiceCorrections!$B$11+S3*ForcedChoiceCorrections!$B$12+T3*ForcedChoiceCorrections!$B$13+U3*ForcedChoiceCorrections!$B$14+V3*ForcedChoiceCorrections!$B$15) | Y3: =IF(AND(ISNUMBER(SEARCH("pass",L3)),ISNUMBER(X3)),COUNTIFS(L$2:L$90,"*pass*",X$2:X$90,">"&X3)+1,"") | Z3: ABS 2021: 35.7% overseas-born, 33.3% non-Eng HH. Belgrave/Lilydale rail; Maroondah Hospital ED nearby (verify drive). | AA3: 2. Ringwood | East Melbourne | Active Shortlist | P: Medium-High (Foothills gateway) | Y: Low (Inland) | Lens: Rail, services & access to greener surroundings | Price: 1045000 | Basis: Sale median, rolling 12m (OnTheHouse); unit $650k | Note: ABS 2021: 35.7% overseas-born, 33.3% non-Eng HH. Belgrave/Lilydale rail; Maroondah Hospital ED nearby (verify drive). | AB3: Yes | AC3: Ringwood station, Lilydale/Belgrave lines (recall; verify) | AD3: Maroondah Hospital ED | AE3: 1500000 | AF3: Maximum purchase price, excluding transaction and moving costs | AG3: Suburb median | AH3: 26 Oct 2026 | AI3: Pass | AJ3: Published house price ($1,045,000) is under $1.5M cap.
A4: Heidelberg | B4: North-East Melbourne | C4: Active Shortlist | D4: Medium (Yarra parkland) | E4: Low (Inland) | F4: Healthcare-led established suburb option | G4: 1452000 | H4: Sale median, rolling 12m (35 sales); unit $700k | I4: 1539120 | J4: 25 | K4: 4 | L4: Active — provisional pass | O4: =IF(K4="","",ROUND(MAX(0,10*(1-K4/Filters!$B$5)),1)) | W4: =IF(M4="",0,COUNT(M4:V4)) | X4: =IF(W4<10,"",M4*ForcedChoiceCorrections!$B$6+N4*ForcedChoiceCorrections!$B$7+O4*ForcedChoiceCorrections!$B$8+P4*ForcedChoiceCorrections!$B$9+Q4*ForcedChoiceCorrections!$B$10+R4*ForcedChoiceCorrections!$B$11+S4*ForcedChoiceCorrections!$B$12+T4*ForcedChoiceCorrections!$B$13+U4*ForcedChoiceCorrections!$B$14+V4*ForcedChoiceCorrections!$B$15) | Y4: =IF(AND(ISNUMBER(SEARCH("pass",L4)),ISNUMBER(X4)),COUNTIFS(L$2:L$90,"*pass*",X$2:X$90,">"&X4)+1,"") | Z4: ABS 2021: 28.1% overseas-born, 28.4% non-Eng HH. Austin Hospital precinct; verify residential pocket & gradients. | AA4: 3. Heidelberg | North-East Melbourne | Active Shortlist | P: Medium (Yarra parkland) | Y: Low (Inland) | Lens: Healthcare-led established suburb option | Price: 1452000 | Basis: Sale median, rolling 12m (35 sales); unit $700k | Note: ABS 2021: 28.1% overseas-born, 28.4% non-Eng HH. Austin Hospital precinct; verify residential pocket & gradients. | AB4: Yes | AC4: Heidelberg station, Hurstbridge line (recall; verify) | AD4: Austin Hospital ED | AE4: 1500000 | AF4: Maximum purchase price, excluding transaction and moving costs | AG4: Suburb median | AH4: 26 Oct 2026 | AI4: Pass | AJ4: House median $1.452M (35 sales) is under $1.5M cap. Passes GW drive (25m) and ED drive (4m).
A5: Eltham | B5: North-East Melbourne | C5: Active Shortlist | D5: High (Bushland/trees) | E5: Low (Inland) | F5: Green/scenic lifestyle hypothesis | G5: 1273000 | H5: Sale median, rolling 12m (195 sales); unit $805k | I5: 1349380 | J5: 26 | K5: 16 | L5: Active — provisional pass | O5: =IF(K5="","",ROUND(MAX(0,10*(1-K5/Filters!$B$5)),1)) | W5: =IF(M5="",0,COUNT(M5:V5)) | X5: =IF(W5<10,"",M5*ForcedChoiceCorrections!$B$6+N5*ForcedChoiceCorrections!$B$7+O5*ForcedChoiceCorrections!$B$8+P5*ForcedChoiceCorrections!$B$9+Q5*ForcedChoiceCorrections!$B$10+R5*ForcedChoiceCorrections!$B$11+S5*ForcedChoiceCorrections!$B$12+T5*ForcedChoiceCorrections!$B$13+U5*ForcedChoiceCorrections!$B$14+V5*ForcedChoiceCorrections!$B$15) | Y5: =IF(AND(ISNUMBER(SEARCH("pass",L5)),ISNUMBER(X5)),COUNTIFS(L$2:L$90,"*pass*",X$2:X$90,">"&X5)+1,"") | Z5: ABS 2021: 18.5% overseas-born, 14.0% non-Eng HH. Hurstbridge line; verify ED & GW drive times. | AA5: 4. Eltham | North-East Melbourne | Active Shortlist | P: High (Bushland/trees) | Y: Low (Inland) | Lens: Green/scenic lifestyle hypothesis | Price: 1273000 | Basis: Sale median, rolling 12m (195 sales); unit $805k | Note: ABS 2021: 18.5% overseas-born, 14.0% non-Eng HH. Hurstbridge line; verify ED & GW drive times. | AB5: Yes | AC5: Eltham station, Hurstbridge line (recall; verify) | AD5: Austin Hospital ED | AE5: 1500000 | AF5: Maximum purchase price, excluding transaction and moving costs | AG5: Suburb median | AH5: 26 Oct 2026 | AI5: Pass | AJ5: House median $1.273M (195 sales) is under $1.5M cap. Passes GW drive (26m) and ED drive (16m).
A6: Upper Ferntree Gully | B6: East / Foothills | C6: Active Shortlist | D6: High (Foothills/forest) | E6: Low (Inland) | F6: Forest/foothills lifestyle with hospital & rail access | G6: 872133 | H6: AVM estimate (30 Sep 2026), NOT a verified sale median | I6: 924460.98 | J6: 16 | K6: 2 | L6: Active — provisional pass | O6: =IF(K6="","",ROUND(MAX(0,10*(1-K6/Filters!$B$5)),1)) | W6: =IF(M6="",0,COUNT(M6:V6)) | X6: =IF(W6<10,"",M6*ForcedChoiceCorrections!$B$6+N6*ForcedChoiceCorrections!$B$7+O6*ForcedChoiceCorrections!$B$8+P6*ForcedChoiceCorrections!$B$9+Q6*ForcedChoiceCorrections!$B$10+R6*ForcedChoiceCorrections!$B$11+S6*ForcedChoiceCorrections!$B$12+T6*ForcedChoiceCorrections!$B$13+U6*ForcedChoiceCorrections!$B$14+V6*ForcedChoiceCorrections!$B$15) | Y6: =IF(AND(ISNUMBER(SEARCH("pass",L6)),ISNUMBER(X6)),COUNTIFS(L$2:L$90,"*pass*",X$2:X$90,">"&X6)+1,"") | Z6: ABS 2021: 19.2% overseas-born, 12.2% non-Eng HH. Belgrave line; 10-min walk/bus 732 to Angliss Hospital (verify 24-hr ED status & drive). | AA6: 5. Upper Ferntree Gully | East / Foothills | Active Shortlist | P: High (Foothills/forest) | Y: Low (Inland) | Lens: Forest/foothills lifestyle with hospital & rail access | Price: 872133 | Basis: AVM estimate (30 Sep 2026), NOT a verified sale median | Note: ABS 2021: 19.2% overseas-born, 12.2% non-Eng HH. Belgrave line; 10-min walk/bus 732 to Angliss Hospital (verify 24-hr ED status & drive). | AB6: Yes | AC6: Upper Ferntree Gully station, Belgrave line (per sheet note) | AD6: Angliss Hospital ED (24-hr status still to verify) | AE6: 1500000 | AF6: Maximum purchase price, excluding transaction and moving costs | AG6: Suburb median | AH6: 26 Oct 2026 | AI6: Pass | AJ6: Published house price ($872,133) is under $1.5M cap.
A7: Glen Waverley | B7: East Melbourne | C7: Active Shortlist | D7: Low-Medium (Suburban) | E7: Low (Inland) | F7: Current stay baseline — multicultural convenience | G7: 1763500 | H7: Sale median, rolling 12m (454 sales); unit $930k | I7: 1869310 | J7: 0 | K7: 13 | L7: Active — needs data | O7: =IF(K7="","",ROUND(MAX(0,10*(1-K7/Filters!$B$5)),1)) | W7: =IF(M7="",0,COUNT(M7:V7)) | X7: =IF(W7<10,"",M7*ForcedChoiceCorrections!$B$6+N7*ForcedChoiceCorrections!$B$7+O7*ForcedChoiceCorrections!$B$8+P7*ForcedChoiceCorrections!$B$9+Q7*ForcedChoiceCorrections!$B$10+R7*ForcedChoiceCorrections!$B$11+S7*ForcedChoiceCorrections!$B$12+T7*ForcedChoiceCorrections!$B$13+U7*ForcedChoiceCorrections!$B$14+V7*ForcedChoiceCorrections!$B$15) | Y7: =IF(AND(ISNUMBER(SEARCH("pass",L7)),ISNUMBER(X7)),COUNTIFS(L$2:L$90,"*pass*",X$2:X$90,">"&X7)+1,"") | Z7: ABS 2021: 58.7% overseas-born, 63.0% non-Eng HH. Baseline benchmark for family proximity. | AA7: 6. Glen Waverley | East Melbourne | Active Shortlist | P: Low-Medium (Suburban) | Y: Low (Inland) | Lens: Current stay baseline — multicultural convenience | Price: 1763500 | Basis: Sale median, rolling 12m (454 sales); unit $930k | Note: ABS 2021: 58.7% overseas-born, 63.0% non-Eng HH. Baseline benchmark for family proximity. | AB7: Yes | AC7: Glen Waverley station, Glen Waverley line (recall; verify) | AD7: Monash Medical Centre Clayton ED | AE7: 1500000 | AF7: Maximum purchase price, excluding transaction and moving costs | AG7: Suburb median | AH7: 26 Oct 2026 | AI7: Needs data | AJ7: House median $1.76M (454 sales) exceeds $1.5M cap; unit median $930k. Awaiting documented search for suitable single-level homes/units under $1.5M.
A8: Warrandyte | B8: North-East / Yarra | C8: Active Shortlist | D8: High (River & state park) | E8: Low (River, non-coastal) | F8: River-and-bush living within metro boundary | H8: Not verified in report | J8: 20 | K8: 14 | L8: Needs data | O8: =IF(K8="","",ROUND(MAX(0,10*(1-K8/Filters!$B$5)),1)) | W8: =IF(M8="",0,COUNT(M8:V8)) | X8: =IF(W8<10,"",M8*ForcedChoiceCorrections!$B$6+N8*ForcedChoiceCorrections!$B$7+O8*ForcedChoiceCorrections!$B$8+P8*ForcedChoiceCorrections!$B$9+Q8*ForcedChoiceCorrections!$B$10+R8*ForcedChoiceCorrections!$B$11+S8*ForcedChoiceCorrections!$B$12+T8*ForcedChoiceCorrections!$B$13+U8*ForcedChoiceCorrections!$B$14+V8*ForcedChoiceCorrections!$B$15) | Y8: =IF(AND(ISNUMBER(SEARCH("pass",L8)),ISNUMBER(X8)),COUNTIFS(L$2:L$90,"*pass*",X$2:X$90,">"&X8)+1,"") | Z8: ABS 2021: 17.7% aged 65+, 17.0% non-Eng HH. Direct city bus 906; no local rail; check fire overlay & ED drive. | AA8: 7. Warrandyte | North-East / Yarra | Active Shortlist | P: High (River & state park) | Y: Low (River, non-coastal) | Lens: River-and-bush living within metro boundary | Price: [Blank] | Basis: Not verified in report | Note: ABS 2021: 17.7% aged 65+, 17.0% non-Eng HH. Direct city bus 906; no local rail; check fire overlay & ED drive. | AB8: No | AC8: No rail; bus 906 (per sheet note) | AD8: Maroondah Hospital ED | AE8: 1500000 | AF8: Maximum purchase price, excluding transaction and moving costs | AG8: [Awaiting search] | AH8: 26 Oct 2026 | AI8: Needs data | AJ8: No verified pricing entered.
A9: Diamond Creek | B9: North-East Fringe | C9: Active Shortlist | D9: High (Green wedge & trail) | E9: Low (Inland) | F9: Practical metro nature compromise with rail | G9: 885000 | H9: 3-bed house median $885k; 4-bed $1,240k (Domain) | I9: 938100 | J9: 33 | K9: 19 | L9: Active — provisional pass | O9: =IF(K9="","",ROUND(MAX(0,10*(1-K9/Filters!$B$5)),1)) | W9: =IF(M9="",0,COUNT(M9:V9)) | X9: =IF(W9<10,"",M9*ForcedChoiceCorrections!$B$6+N9*ForcedChoiceCorrections!$B$7+O9*ForcedChoiceCorrections!$B$8+P9*ForcedChoiceCorrections!$B$9+Q9*ForcedChoiceCorrections!$B$10+R9*ForcedChoiceCorrections!$B$11+S9*ForcedChoiceCorrections!$B$12+T9*ForcedChoiceCorrections!$B$13+U9*ForcedChoiceCorrections!$B$14+V9*ForcedChoiceCorrections!$B$15) | Y9: =IF(AND(ISNUMBER(SEARCH("pass",L9)),ISNUMBER(X9)),COUNTIFS(L$2:L$90,"*pass*",X$2:X$90,">"&X9)+1,"") | Z9: ABS 2021: 13.1% aged 65+, 12.2% non-Eng HH. Hurstbridge line station & trail; verify ED & GW drive. | AA9: 8. Diamond Creek | North-East Fringe | Active Shortlist | P: High (Green wedge & trail) | Y: Low (Inland) | Lens: Practical metro nature compromise with rail | Price: 885000 | Basis: 3-bed house median $885k; 4-bed $1,240k (Domain) | Note: ABS 2021: 13.1% aged 65+, 12.2% non-Eng HH. Hurstbridge line station & trail; verify ED & GW drive. | AB9: Yes | AC9: Diamond Creek station, Hurstbridge line (per sheet note) | AD9: Austin Hospital ED | AE9: 1500000 | AF9: Maximum purchase price, excluding transaction and moving costs | AG9: Suburb median | AH9: 26 Oct 2026 | AI9: Pass | AJ9: Published house price ($885,000) is under $1.5M cap.
A10: Mentone | B10: Bayside Melbourne | C10: Active Shortlist | D10: Low-Medium (Suburban gardens) | E10: High (Bay beach) | F10: Coastal daily living on metro rail line | G10: 1497099 | H10: Sale median (Aussie/CoreLogic); Woodards shows $1.30m | I10: 1586924.9 | J10: 25 | K10: 16 | L10: Active — provisional pass | O10: =IF(K10="","",ROUND(MAX(0,10*(1-K10/Filters!$B$5)),1)) | W10: =IF(M10="",0,COUNT(M10:V10)) | X10: =IF(W10<10,"",M10*ForcedChoiceCorrections!$B$6+N10*ForcedChoiceCorrections!$B$7+O10*ForcedChoiceCorrections!$B$8+P10*ForcedChoiceCorrections!$B$9+Q10*ForcedChoiceCorrections!$B$10+R10*ForcedChoiceCorrections!$B$11+S10*ForcedChoiceCorrections!$B$12+T10*ForcedChoiceCorrections!$B$13+U10*ForcedChoiceCorrections!$B$14+V10*ForcedChoiceCorrections!$B$15) | Y10: =IF(AND(ISNUMBER(SEARCH("pass",L10)),ISNUMBER(X10)),COUNTIFS(L$2:L$90,"*pass*",X$2:X$90,">"&X10)+1,"") | Z10: ABS 2021: 28.8% overseas-born, 22.4% non-Eng HH. Reconcile price sources & verify ED drive. | AA10: 9. Mentone | Bayside Melbourne | Active Shortlist | P: Low-Medium (Suburban gardens) | Y: High (Bay beach) | Lens: Coastal daily living on metro rail line | Price: 1497099 | Basis: Sale median (Aussie/CoreLogic); Woodards shows $1.30m | Note: ABS 2021: 28.8% overseas-born, 22.4% non-Eng HH. Reconcile price sources & verify ED drive. | AB10: Yes | AC10: Mentone station, Frankston line (recall; verify) | AD10: Monash Medical Centre Clayton ED | AE10: 1500000 | AF10: Maximum purchase price, excluding transaction and moving costs | AG10: Suburb median | AH10: 26 Oct 2026 | AI10: Pass | AJ10: House median $1.497M (CoreLogic) / $1.30M (Woodards) is under $1.5M cap. Passes GW drive (25m) and ED drive (16m).
A11: Frankston | B11: South / Coastal | C11: Active Shortlist | D11: Medium (Sweetwater/gullies) | E11: High (Bay beach) | F11: Coastal practicality & accessible property price | G11: 834296 | H11: Sale median, rolling 12m (Aussie/Cotality); unit $573k | I11: 884353.76 | J11: 25 | K11: 4 | L11: Active — provisional pass | O11: =IF(K11="","",ROUND(MAX(0,10*(1-K11/Filters!$B$5)),1)) | W11: =IF(M11="",0,COUNT(M11:V11)) | X11: =IF(W11<10,"",M11*ForcedChoiceCorrections!$B$6+N11*ForcedChoiceCorrections!$B$7+O11*ForcedChoiceCorrections!$B$8+P11*ForcedChoiceCorrections!$B$9+Q11*ForcedChoiceCorrections!$B$10+R11*ForcedChoiceCorrections!$B$11+S11*ForcedChoiceCorrections!$B$12+T11*ForcedChoiceCorrections!$B$13+U11*ForcedChoiceCorrections!$B$14+V11*ForcedChoiceCorrections!$B$15) | Y11: =IF(AND(ISNUMBER(SEARCH("pass",L11)),ISNUMBER(X11)),COUNTIFS(L$2:L$90,"*pass*",X$2:X$90,">"&X11)+1,"") | Z11: ABS 2021: 22.5% overseas-born, 15.2% non-Eng HH. Peninsula Univ Hospital ED; ~66m train to CBD. | AA11: 10. Frankston | South / Coastal | Active Shortlist | P: Medium (Sweetwater/gullies) | Y: High (Bay beach) | Lens: Coastal practicality & accessible property price | Price: 834296 | Basis: Sale median, rolling 12m (Aussie/Cotality); unit $573k | Note: ABS 2021: 22.5% overseas-born, 15.2% non-Eng HH. Peninsula Univ Hospital ED; ~66m train to CBD. | AB11: Yes | AC11: Frankston station, Frankston line (recall; verify) | AD11: Peninsula University Hospital ED | AE11: 1500000 | AF11: Maximum purchase price, excluding transaction and moving costs | AG11: Suburb median | AH11: 26 Oct 2026 | AI11: Pass | AJ11: Published house price ($834,296) is under $1.5M cap.
A12: Altona | B12: West Coastal | C12: Active Shortlist | D12: Low-Medium (Flat coastal) | E12: High (Bay beach/wetlands) | F12: Coastal village alternative at lower price point | G12: 1155073 | H12: AVM estimate (31 Aug 2026), NOT a verified sale median | I12: 1224377.4 | J12: 35 | K12: 15 | L12: Active — provisional pass | O12: =IF(K12="","",ROUND(MAX(0,10*(1-K12/Filters!$B$5)),1)) | W12: =IF(M12="",0,COUNT(M12:V12)) | X12: =IF(W12<10,"",M12*ForcedChoiceCorrections!$B$6+N12*ForcedChoiceCorrections!$B$7+O12*ForcedChoiceCorrections!$B$8+P12*ForcedChoiceCorrections!$B$9+Q12*ForcedChoiceCorrections!$B$10+R12*ForcedChoiceCorrections!$B$11+S12*ForcedChoiceCorrections!$B$12+T12*ForcedChoiceCorrections!$B$13+U12*ForcedChoiceCorrections!$B$14+V12*ForcedChoiceCorrections!$B$15) | Y12: =IF(AND(ISNUMBER(SEARCH("pass",L12)),ISNUMBER(X12)),COUNTIFS(L$2:L$90,"*pass*",X$2:X$90,">"&X12)+1,"") | Z12: ABS 2021: 28.3% overseas-born, 23.8% non-Eng HH. Cross-city drive to Glen Waverley needs testing. | AA12: 11. Altona | West Coastal | Active Shortlist | P: Low-Medium (Flat coastal) | Y: High (Bay beach/wetlands) | Lens: Coastal village alternative at lower price point | Price: 1155073 | Basis: AVM estimate (31 Aug 2026), NOT a verified sale median | Note: ABS 2021: 28.3% overseas-born, 23.8% non-Eng HH. Cross-city drive to Glen Waverley needs testing. | AB12: Yes | AC12: Altona station, Werribee line (recall; verify) | AD12: Footscray Hospital ED | AE12: 1500000 | AF12: Maximum purchase price, excluding transaction and moving costs | AG12: Suburb median | AH12: 26 Oct 2026 | AI12: Pass | AJ12: Published house price ($1,155,073) is under $1.5M cap.
A13: Williamstown | B13: West Coastal | C13: Active Shortlist | D13: Medium (Botanic gardens) | E13: High (Historic harbor/beach) | F13: Picturesque coastal character vs cost | G13: 1642163 | H13: AVM estimate (30 Sep 2026), NOT a verified sale median | I13: 1740692.8 | J13: 31 | K13: 13 | L13: Active — needs data | O13: =IF(K13="","",ROUND(MAX(0,10*(1-K13/Filters!$B$5)),1)) | W13: =IF(M13="",0,COUNT(M13:V13)) | X13: =IF(W13<10,"",M13*ForcedChoiceCorrections!$B$6+N13*ForcedChoiceCorrections!$B$7+O13*ForcedChoiceCorrections!$B$8+P13*ForcedChoiceCorrections!$B$9+Q13*ForcedChoiceCorrections!$B$10+R13*ForcedChoiceCorrections!$B$11+S13*ForcedChoiceCorrections!$B$12+T13*ForcedChoiceCorrections!$B$13+U13*ForcedChoiceCorrections!$B$14+V13*ForcedChoiceCorrections!$B$15) | Y13: =IF(AND(ISNUMBER(SEARCH("pass",L13)),ISNUMBER(X13)),COUNTIFS(L$2:L$90,"*pass*",X$2:X$90,">"&X13)+1,"") | Z13: ABS 2021: 22.6% overseas-born, 20.0% non-Eng HH. Cross-city travel to Glen Waverley & ED capacity need checking. | AA13: 12. Williamstown | West Coastal | Active Shortlist | P: Medium (Botanic gardens) | Y: High (Historic harbor/beach) | Lens: Picturesque coastal character vs cost | Price: 1642163 | Basis: AVM estimate (30 Sep 2026), NOT a verified sale median | Note: ABS 2021: 22.6% overseas-born, 20.0% non-Eng HH. Cross-city travel to Glen Waverley & ED capacity need checking. | AB13: Yes | AC13: Williamstown station, Williamstown line (recall; verify) | AD13: Footscray Hospital ED | AE13: 1500000 | AF13: Maximum purchase price, excluding transaction and moving costs | AG13: AVM estimate | AH13: 26 Oct 2026 | AI13: Needs data | AJ13: Figure is an automated valuation model ($1.64M), not a verified sale median or specific property. Awaiting documented listing search under $1.5M.
A14: Healesville | B14: Yarra Valley | C14: Active Shortlist | D14: High (Valley & mountains) | E14: Low (Inland) | F14: Larger Yarra Valley town comparator | H14: Not verified in report | J14: 43 | K14: 33 | L14: Needs data | O14: =IF(K14="","",ROUND(MAX(0,10*(1-K14/Filters!$B$5)),1)) | W14: =IF(M14="",0,COUNT(M14:V14)) | X14: =IF(W14<10,"",M14*ForcedChoiceCorrections!$B$6+N14*ForcedChoiceCorrections!$B$7+O14*ForcedChoiceCorrections!$B$8+P14*ForcedChoiceCorrections!$B$9+Q14*ForcedChoiceCorrections!$B$10+R14*ForcedChoiceCorrections!$B$11+S14*ForcedChoiceCorrections!$B$12+T14*ForcedChoiceCorrections!$B$13+U14*ForcedChoiceCorrections!$B$14+V14*ForcedChoiceCorrections!$B$15) | Y14: =IF(AND(ISNUMBER(SEARCH("pass",L14)),ISNUMBER(X14)),COUNTIFS(L$2:L$90,"*pass*",X$2:X$90,">"&X14)+1,"") | Z14: 2021 pop 7,589. CAUTION: Eastern Health directs urgent ED patients to Maroondah Hospital ED (not local). | AA14: 13. Healesville | Yarra Valley | Active Shortlist | P: High (Valley & mountains) | Y: Low (Inland) | Lens: Larger Yarra Valley town comparator | Price: [Blank] | Basis: Not verified in report | Note: 2021 pop 7,589. CAUTION: Eastern Health directs urgent ED patients to Maroondah Hospital ED (not local). | AB14: No | AC14: No rail (recall; verify) | AD14: Maroondah Hospital ED (sheet note: urgent ED cases go here) | AE14: 1500000 | AF14: Maximum purchase price, excluding transaction and moving costs | AG14: [Awaiting search] | AH14: 26 Oct 2026 | AI14: Needs data | AJ14: No verified pricing entered.
A15: Kyneton | B15: Macedon Ranges | C15: Active Shortlist | D15: High (Country town & gardens) | E15: Low (Inland river) | F15: Country-town practicality with V/Line rail | G15: 810000 | H15: 3-bed house median $810k; 4-bed $980k (Domain) | I15: 858600 | J15: 77 | K15: 47 | L15: Active — provisional pass | O15: =IF(K15="","",ROUND(MAX(0,10*(1-K15/Filters!$B$5)),1)) | W15: =IF(M15="",0,COUNT(M15:V15)) | X15: =IF(W15<10,"",M15*ForcedChoiceCorrections!$B$6+N15*ForcedChoiceCorrections!$B$7+O15*ForcedChoiceCorrections!$B$8+P15*ForcedChoiceCorrections!$B$9+Q15*ForcedChoiceCorrections!$B$10+R15*ForcedChoiceCorrections!$B$11+S15*ForcedChoiceCorrections!$B$12+T15*ForcedChoiceCorrections!$B$13+U15*ForcedChoiceCorrections!$B$14+V15*ForcedChoiceCorrections!$B$15) | Y15: =IF(AND(ISNUMBER(SEARCH("pass",L15)),ISNUMBER(X15)),COUNTIFS(L$2:L$90,"*pass*",X$2:X$90,">"&X15)+1,"") | Z15: ABS 2021: 25.0% aged 65+, 6.9% non-Eng HH. CAUTION: Local facility is 24-hr Urgent Care Centre, NOT a major public ED. | AA15: 14. Kyneton | Macedon Ranges | Active Shortlist | P: High (Country town & gardens) | Y: Low (Inland river) | Lens: Country-town practicality with V/Line rail | Price: 810000 | Basis: 3-bed house median $810k; 4-bed $980k (Domain) | Note: ABS 2021: 25.0% aged 65+, 6.9% non-Eng HH. CAUTION: Local facility is 24-hr Urgent Care Centre, NOT a major public ED. | AB15: Yes | AC15: Kyneton station, V/Line Bendigo (per sheet note) | AD15: Bendigo Hospital ED (local 24-hr urgent care is not an ED) | AE15: 1500000 | AF15: Maximum purchase price, excluding transaction and moving costs | AG15: Suburb median | AH15: 26 Oct 2026 | AI15: Pass | AJ15: Published house price ($810,000) is under $1.5M cap.
A16: Woodend | B16: Macedon Ranges | C16: Active Shortlist | D16: High (Macedon Ranges forest) | E16: Low (Inland) | F16: Walkable station country town in Macedon Ranges | G16: 890000 | H16: 3-bed house median $890k; 4-bed $1,150k (Domain) | I16: 943400 | J16: 68 | K16: 55 | L16: Active — provisional pass | O16: =IF(K16="","",ROUND(MAX(0,10*(1-K16/Filters!$B$5)),1)) | W16: =IF(M16="",0,COUNT(M16:V16)) | X16: =IF(W16<10,"",M16*ForcedChoiceCorrections!$B$6+N16*ForcedChoiceCorrections!$B$7+O16*ForcedChoiceCorrections!$B$8+P16*ForcedChoiceCorrections!$B$9+Q16*ForcedChoiceCorrections!$B$10+R16*ForcedChoiceCorrections!$B$11+S16*ForcedChoiceCorrections!$B$12+T16*ForcedChoiceCorrections!$B$13+U16*ForcedChoiceCorrections!$B$14+V16*ForcedChoiceCorrections!$B$15) | Y16: =IF(AND(ISNUMBER(SEARCH("pass",L16)),ISNUMBER(X16)),COUNTIFS(L$2:L$90,"*pass*",X$2:X$90,">"&X16)+1,"") | Z16: V/Line Bendigo line. Check winter comfort, major public ED drive time & family trip frequency. | AA16: 15. Woodend | Macedon Ranges | Active Shortlist | P: High (Macedon Ranges forest) | Y: Low (Inland) | Lens: Walkable station country town in Macedon Ranges | Price: 890000 | Basis: 3-bed house median $890k; 4-bed $1,150k (Domain) | Note: V/Line Bendigo line. Check winter comfort, major public ED drive time & family trip frequency. | AB16: Yes | AC16: Woodend station, V/Line Bendigo (per sheet note) | AD16: Bendigo Hospital ED (nearest ED not confirmed; Northern Hospital Epping not tested) | AE16: 1500000 | AF16: Maximum purchase price, excluding transaction and moving costs | AG16: Suburb median | AH16: 26 Oct 2026 | AI16: Pass | AJ16: Published house price ($890,000) is under $1.5M cap.
A17: Macedon | B17: Macedon Ranges | C17: Active Shortlist | D17: High (Forest & Honour Ave) | E17: Low (Inland) | F17: Landscape-led Macedon Ranges option | H17: Not verified in report | J17: 62 | K17: 60 | L17: Needs data | O17: =IF(K17="","",ROUND(MAX(0,10*(1-K17/Filters!$B$5)),1)) | W17: =IF(M17="",0,COUNT(M17:V17)) | X17: =IF(W17<10,"",M17*ForcedChoiceCorrections!$B$6+N17*ForcedChoiceCorrections!$B$7+O17*ForcedChoiceCorrections!$B$8+P17*ForcedChoiceCorrections!$B$9+Q17*ForcedChoiceCorrections!$B$10+R17*ForcedChoiceCorrections!$B$11+S17*ForcedChoiceCorrections!$B$12+T17*ForcedChoiceCorrections!$B$13+U17*ForcedChoiceCorrections!$B$14+V17*ForcedChoiceCorrections!$B$15) | Y17: =IF(AND(ISNUMBER(SEARCH("pass",L17)),ISNUMBER(X17)),COUNTIFS(L$2:L$90,"*pass*",X$2:X$90,">"&X17)+1,"") | Z17: Distinguish Macedon from Mount Macedon; check bushfire overlay, gradients & major ED journey. | AA17: 16. Macedon | Macedon Ranges | Active Shortlist | P: High (Forest & Honour Ave) | Y: Low (Inland) | Lens: Landscape-led Macedon Ranges option | Price: [Blank] | Basis: Not verified in report | Note: Distinguish Macedon from Mount Macedon; check bushfire overlay, gradients & major ED journey. | AB17: Yes | AC17: Macedon station, V/Line Bendigo (recall; verify) | AD17: Bendigo Hospital ED (nearest ED not confirmed; Northern Hospital Epping not tested) | AE17: 1500000 | AF17: Maximum purchase price, excluding transaction and moving costs | AG17: [Awaiting search] | AH17: 26 Oct 2026 | AI17: Needs data | AJ17: No verified pricing entered.
A18: Torquay | B18: Surf Coast | C18: Active Shortlist | D18: Medium (Coastal heath) | E18: High (Surf Coast walk/beach) | F18: Everyday surf-coast walking lifestyle | G18: 1180000 | H18: House sale median $1,180,000; unit $891,250 (REA) | I18: 1250800 | J18: 88 | K18: 23 | L18: Active — provisional pass | O18: =IF(K18="","",ROUND(MAX(0,10*(1-K18/Filters!$B$5)),1)) | W18: =IF(M18="",0,COUNT(M18:V18)) | X18: =IF(W18<10,"",M18*ForcedChoiceCorrections!$B$6+N18*ForcedChoiceCorrections!$B$7+O18*ForcedChoiceCorrections!$B$8+P18*ForcedChoiceCorrections!$B$9+Q18*ForcedChoiceCorrections!$B$10+R18*ForcedChoiceCorrections!$B$11+S18*ForcedChoiceCorrections!$B$12+T18*ForcedChoiceCorrections!$B$13+U18*ForcedChoiceCorrections!$B$14+V18*ForcedChoiceCorrections!$B$15) | Y18: =IF(AND(ISNUMBER(SEARCH("pass",L18)),ISNUMBER(X18)),COUNTIFS(L$2:L$90,"*pass*",X$2:X$90,">"&X18)+1,"") | Z18: ABS 2021: 16.4% aged 65+, 7.4% non-Eng HH. Bus 54 to Marshall Station; relies on Univ Hospital Geelong for major public ED. | AA18: 17. Torquay | Surf Coast | Active Shortlist | P: Medium (Coastal heath) | Y: High (Surf Coast walk/beach) | Lens: Everyday surf-coast walking lifestyle | Price: 1180000 | Basis: House sale median $1,180,000; unit $891,250 (REA) | Note: ABS 2021: 16.4% aged 65+, 7.4% non-Eng HH. Bus 54 to Marshall Station; relies on Univ Hospital Geelong for major public ED. | AB18: No | AC18: No rail; bus 54 to Marshall Station (per sheet note) | AD18: University Hospital Geelong ED | AE18: 1500000 | AF18: Maximum purchase price, excluding transaction and moving costs | AG18: Suburb median | AH18: 26 Oct 2026 | AI18: Pass | AJ18: House median $1.180M is under $1.5M cap. Passes GW drive (88m <= 90m cap) and ED drive (23m).
A19: Ocean Grove | B19: Bellarine Peninsula | C19: Active Shortlist | D19: Medium-High (Nature reserve) | E19: High (Beach + woodland) | F19: Coast-plus-bushland alternative to Torquay | G19: 980000 | H19: House sale median $980,000 (325 sales); unit $770k | I19: 1038800 | J19: 92 | K19: 21 | L19: Fails: GW drive | O19: =IF(K19="","",ROUND(MAX(0,10*(1-K19/Filters!$B$5)),1)) | W19: =IF(M19="",0,COUNT(M19:V19)) | X19: =IF(W19<10,"",M19*ForcedChoiceCorrections!$B$6+N19*ForcedChoiceCorrections!$B$7+O19*ForcedChoiceCorrections!$B$8+P19*ForcedChoiceCorrections!$B$9+Q19*ForcedChoiceCorrections!$B$10+R19*ForcedChoiceCorrections!$B$11+S19*ForcedChoiceCorrections!$B$12+T19*ForcedChoiceCorrections!$B$13+U19*ForcedChoiceCorrections!$B$14+V19*ForcedChoiceCorrections!$B$15) | Y19: =IF(AND(ISNUMBER(SEARCH("pass",L19)),ISNUMBER(X19)),COUNTIFS(L$2:L$90,"*pass*",X$2:X$90,">"&X19)+1,"") | Z19: ABS 2021: 22.2% aged 65+, 5.1% non-Eng HH. 143-ha Nature Reserve; bus 55/56 to Geelong; relies on Univ Hospital Geelong ED. | AA19: 18. Ocean Grove | Bellarine Peninsula | Active Shortlist | P: Medium-High (Nature reserve) | Y: High (Beach + woodland) | Lens: Coast-plus-bushland alternative to Torquay | Price: 980000 | Basis: House sale median $980,000 (325 sales); unit $770k | Note: ABS 2021: 22.2% aged 65+, 5.1% non-Eng HH. 143-ha Nature Reserve; bus 55/56 to Geelong; relies on Univ Hospital Geelong ED. | AB19: No | AC19: No rail; bus 55/56 to Geelong (per sheet note) | AD19: University Hospital Geelong ED | AE19: 1500000 | AF19: Maximum purchase price, excluding transaction and moving costs | AG19: Suburb median | AH19: 26 Oct 2026 | AI19: Pass | AJ19: Published house price ($980,000) is under $1.5M cap.
