Workbook

Sheet Start here
A1: Parents' move — priorities survey
A2: For Mum, Dad and me. Fill in the yellow cells only; everything else calculates.
A4: How to run it
A5: 1. Fill in your own column (Me) first, before you interview them, so their answers can't shift yours.
A6: 2. Ask Mum and Dad separately. Read each question and its options aloud on the Survey sheet; type one letter.
A7: 3. E = none of these / depends. Write what they actually said in Notes.
A8: 4. Q15: no more than two D (Essential) answers each. The check under Q15 flags it.
A9: 5. Don't show them Results or your draft weights until everyone has answered.
A10: 6. Open Results for filters, final weights, what to discuss and next steps. Then score suburbs on the Suburb scorecard.
A12: Settings (editable)
A13: Setting | B13: Value | C13: Note
A14: Say in the decision — Mum | B14: 1 | C14: Equal say by default. Lower 'Me' (e.g. 0.5) if Mum and Dad should carry more weight as the buyers.
A15: Say in the decision — Dad | B15: 1
A16: Say in the decision — Me | B16: 1
A18: Q15 answer | B18: Meaning | C18: Score
A19: A | B19: Not needed | C19: 0
A20: B | B20: Nice to have | C20: 1
A21: C | B21: Important | C21: 2
A22: D | B22: Essential | C22: 4 | D22: D = 4 (not 3) so the capped top tier carries real weight. Set it to 3 for flatter weights.
A23: Max D answers per person (Q15) | B23: 2
A25: Purchase costs (stamp duty, fees) as % of price | B25: 0.06 | C25: Estimate only. Check with the Victorian SRO stamp duty calculator before relying on it.
A26: Forced-choice margin | B26: 0.02 | C26: When a Q10–13 pick contradicts Q15, the picked side is moved this far ahead of the other.
A28: Example answer: Q4 — Mum C, Dad B, Me C → Glen Waverley drive limit = 25 min (the strictest answer wins).

Sheet Survey
A1: Survey — read each question aloud, one letter per person
A2: E = none of these / depends (write what they said in Notes). Ask Mum and Dad separately.
A4: # | B4: Section | C4: Question (read aloud) | D4: A | E4: B | F4: C | G4: D | H4: Mum | I4: Dad | J4: Me | K4: Notes
A5: Q1 | B5: Warm-up | C5: What did you love most about daily life in Coorabell? | D5: Green views and quiet | E5: Being near the beach | F5: The village and its people | G5: The space and the garden
A6: Q2 | B6: Warm-up | C6: What was hardest about Coorabell day to day? | D6: Driving everywhere | E6: Being far from family | F6: Being far from doctors and the hospital | G6: Looking after the house and land
A7: Q3 | B7: Dealbreakers | C7: What's the most you'd spend in total, including stamp duty and moving? | D7: $1.0m | E7: $1.25m | F7: $1.5m | G7: More, for the right place
A8: Q4 | B8: Dealbreakers | C8: What's the longest drive to the family in Glen Waverley you'd accept? | D8: 15 min | E8: 25 min | F8: 35 min | G8: 45 min or more
A9: Q5 | B9: Dealbreakers | C9: What's the longest drive to a hospital emergency department you'd accept? | D9: 10 min | E9: 20 min | F9: 30 min | G9: It doesn't matter much
A10: Q6 | B10: Dealbreakers | C10: Stairs inside the home? | D10: None at all | E10: Fine if the bedroom and bathroom are downstairs | F10: Fine anywhere | G10: —
A11: Q7 | B11: Dealbreakers | C11: Garden? | D11: Small, low upkeep | E11: Medium, room to grow things | F11: Large, lots of trees | G11: No garden is fine
A12: Q7b | B12: Dealbreakers (new) | C12: With all three of us living together, the home needs: | D12: 3 bedrooms | E12: 3 bedrooms + a second living area | F12: 4 bedrooms | G12: A self-contained space (granny flat or separate unit)
A13: Q8 | B13: What it means | C13: When you picture nature near your new home, it's mostly: | D13: A green outlook from the house | E13: Bush walks within a short drive | F13: Hills and forest all around | G13: Your own garden
A14: Q9 | B14: What it means | C14: Which one thing would make you feel most at home in the community? | D14: A church or place of worship nearby | E14: Indian groceries and restaurants | F14: Friends who share your language or culture | G14: Friendly neighbours of any background
A15: Q10 | B15: Trade-off: pick one | C15: Which would you choose? | D15: A forest street, 35 min from Glen Waverley | E15: A leafy suburban street, 15 min from Glen Waverley | F15: — | G15: —
A16: Q11 | B16: Trade-off: pick one | C16: Which would you choose? | D16: Flat suburban streets, beach 10 min away | E16: Hills and bush, beach an hour away | F16: — | G16: —
... A30: Q15.10 | B30: Priorities (new) | C30: Easy trip to the city (work, outings) | D30: Not needed | E30: Nice to have | F30: Important | G30: Essential
C32: Q15: number of D answers (max 2) | H32: =COUNTIF(H21:H30,"D") -> 0 | I32: =COUNTIF(I21:I30,"D") -> 0 | J32: =COUNTIF(J21:J30,"D") -> 0
C33: Q15: rows answered (of 10) | H33: =COUNTA(H21:H30) -> 0 | I33: =COUNTA(I21:I30) -> 0 | J33: =COUNTA(J21:J30) -> 0
C34: Q15 status | H34: =IF(H33=0,"Not started",IF(H32>'Start here'!$B$23,"Too many D's",IF(H33<10,"Incomplete","OK"))) -> Not started | I34: =IF(I33=0,"Not started",IF(I32>'Start here'!$B$23,"Too many D's",IF(I33<10,"Incomplete","OK"))) -> Not started | J34: =IF(J33=0,"Not started",IF(J32>'Start here'!$B$23,"Too many D's",IF(J33<10,"Incomplete","OK"))) -> Not started
C35: Q1–Q14: answered (of 15) | H35: =COUNTA(H5:H19) -> 0 | I35: =COUNTA(I5:I19) -> 0 | J35: =COUNTA(J5:J19) -> 0

Sheet Results
A1: Results — updates as the survey is filled in
A2: Don't show this sheet to Mum and Dad until they've answered. Yellow = your optional tweaks.
A4: ="Answered (of 25): Mum "&(COUNTA(Survey!H5:H19)+COUNTA(Survey!H21:H30))&" · Dad "&(COUNTA(Survey!I5:I19)+COUNTA(Survey!I21:I30))&" · Me "&(COUNTA(Survey!J5:J19)+COUNTA(Survey!J21:J30))&" Q15 check: Mum "&Survey!H34&" · Dad "&Survey!I34&" · Me "&Survey!J34 -> Answered (of 25): Mum 0 · Dad 0 · Me 0 Q15 check: Mum Not started · Dad Not started · Me Not started
A6: 1. Hard filters — rule suburbs out (the strictest answer wins)
A7: Filter | B7: Result | E7: Answers | H7: Notes
A8: Total budget incl. purchase costs | B8: =Calc!E3 -> Not answered | E8: ="Mum "&IF(Survey!H7="","–",UPPER(Survey!H7))&" · Dad "&IF(Survey!I7="","–",UPPER(Survey!I7))&" · Me "&IF(Survey!J7="","–",UPPER(Survey!J7)) -> Mum – · Dad – · Me – | H8: ="Max purchase price ≈ "&IF(ISNUMBER(B8),TEXT(B8/(1+'Start here'!$B$25),"$#,##0"),"—")&" after est. "&TEXT('Start here'!$B$25,"0%")&" costs. Leave your column blank if you're not contributing." -> Max purchase price ≈ — after est. 6% costs. Leave your column blank if you're not contributing.
A9: Max drive to Glen Waverley (min) | B9: =Calc!E4 -> Not answered | E9: ="Mum "&IF(Survey!H8="","–",UPPER(Survey!H8))&" · Dad "&IF(Survey!I8="","–",UPPER(Survey!I8))&" · Me "&IF(Survey!J8="","–",UPPER(Survey!J8)) -> Mum – · Dad – · Me – | H9: ="Rule out suburbs beyond this; it is also weighted in Q15."&IF(COUNTIF(Survey!H8:J8,"D")>0," 45 means '45 min or more'.","") -> Rule out suburbs beyond this; it is also weighted in Q15.
A10: Max drive to an emergency department (min) | B10: =Calc!E5 -> Not answered | E10: ="Mum "&IF(Survey!H9="","–",UPPER(Survey!H9))&" · Dad "&IF(Survey!I9="","–",UPPER(Survey!I9))&" · Me "&IF(Survey!J9="","–",UPPER(Survey!J9)) -> Mum – · Dad – · Me – | H10: ="Measure to a public hospital with a 24-hour emergency department, not just the nearest hospital." -> Measure to a public hospital with a 24-hour emergency department, not just the nearest hospital.
A11: Stairs | B11: =IF(ISNUMBER(Calc!E6),INDEX(Survey!$D$10:$F$10,Calc!E6),"Not answered") -> Not answered | E11: ="Mum "&IF(Survey!H10="","–",UPPER(Survey!H10))&" · Dad "&IF(Survey!I10="","–",UPPER(Survey!I10))&" · Me "&IF(Survey!J10="","–",UPPER(Survey!J10)) -> Mum – · Dad – · Me – | H11: ="Applies to homes, not suburbs: check at inspections." -> Applies to homes, not suburbs: check at inspections.
A12: Home size (three adults) | B12: =IF(ISNUMBER(Calc!E7),INDEX(Survey!$D$12:$G$12,Calc!E7),"Not answered") -> Not answered | E12: ="Mum "&IF(Survey!H12="","–",UPPER(Survey!H12))&" · Dad "&IF(Survey!I12="","–",UPPER(Survey!I12))&" · Me "&IF(Survey!J12="","–",UPPER(Survey!J12)) -> Mum – · Dad – · Me – | H12: ="Applies to listings. More space pushes the real price above suburb medians — check against the budget." -> Applies to listings. More space pushes the real price above suburb medians — check against the budget.
A13: Garden | B13: =IF(Calc!C40=0,"Not answered",IF(Calc!C40>1,"Answers differ — see right",IFERROR(INDEX(Survey!$D$11:$G$11,MATCH(IF(Survey!H11<>"",Survey!H11,IF(Survey!I11<>"",Survey!I11,Survey!J11)),'Start here'!$A$19:$A$22,0)),"None of these — see notes"))) -> Not answered | E13: ="Mum "&IF(Survey!H11="","–",UPPER(Survey!H11))&" · Dad "&IF(Survey!I11="","–",UPPER(Survey!I11))&" · Me "&IF(Survey!J11="","–",UPPER(Survey!J11)) -> Mum – · Dad – · Me – | H13: ="Applies to homes: check at inspections." -> Applies to homes: check at inspections.
A15: 2. Priority weights — Q15 answers, corrected where a Q10–13 pick disagrees
A16: Combined = each person's Q15 scores turned into shares of 100%, then averaged using 'say in the decision'. Tweak = optional ± percentage points (e.g. 3). Final always re-totals to 100%.
A18: Priority | B18: Mum | C18: Dad | D18: Me | E18: Combined | F18: Forced-choice correction | G18: Your tweak (± pts) | H18: Final weight | I18: Rank | J18: Your draft | K18: Change vs draft | L18: Follow up
A19: =Survey!C21 -> Nature and scenery | B19: =IF(Survey!H21="","–",UPPER(Survey!H21)) -> – | C19: =IF(Survey!I21="","–",UPPER(Survey!I21)) -> – | D19: =IF(Survey!J21="","–",UPPER(Survey!J21)) -> – | E19: =IF(Calc!L20="","",Calc!L20) | F19: =IF(Calc!N20="","",Calc!N20) | H19: =IF(OR(Calc!O20="",SUM(Calc!$O$20:$O$29)=0),"",Calc!O20/SUM(Calc!$O$20:$O$29)) | I19: =IF(H19="","",RANK(H19,$H$19:$H$28)) | J19: 0.18 | K19: =IF(H19="","",H19-J19) | L19: =TRIM(IF(N(Calc!M20)>=2,"Discuss together — 2+ levels apart. ","")&IF(COUNTIF(B19:D19,"D")>0,"Ask why it's essential ("&TRIM(IF(B19="D","Mum ","")&IF(C19="D","Dad ","")&IF(D19="D","Me",""))&").",""))
A20: =Survey!C22 -> Near family in Glen Waverley | B20: =IF(Survey!H22="","–",UPPER(Survey!H22)) -> – | C20: =IF(Survey!I22="","–",UPPER(Survey!I22)) -> – | D20: =IF(Survey!J22="","–",UPPER(Survey!J22)) -> – | E20: =IF(Calc!L21="","",Calc!L21) | F20: =IF(Calc!N21="","",Calc!N21) | H20: =IF(OR(Calc!O21="",SUM(Calc!$O$20:$O$29)=0),"",Calc!O21/SUM(Calc!$O$20:$O$29)) | I20: =IF(H20="","",RANK(H20,$H$19:$H$28)) | J20: 0 | K20: =IF(H20="","",H20-J20) | L20: =TRIM(IF(N(Calc!M21)>=2,"Discuss together — 2+ levels apart. ","")&IF(COUNTIF(B20:D20,"D")>0,"Ask why it's essential ("&TRIM(IF(B20="D","Mum ","")&IF(C20="D","Dad ","")&IF(D20="D","Me",""))&").",""))
A21: =Survey!C23 -> Indian/South Asian community | B21: =IF(Survey!H23="","–",UPPER(Survey!H23)) -> – | C21: =IF(Survey!I23="","–",UPPER(Survey!I23)) -> – | D21: =IF(Survey!J23="","–",UPPER(Survey!J23)) -> – | E21: =IF(Calc!L22="","",Calc!L22) | F21: =IF(Calc!N22="","",Calc!N22) | H21: =IF(OR(Calc!O22="",SUM(Calc!$O$20:$O$29)=0),"",Calc!O22/SUM(Calc!$O$20:$O$29)) | I21: =IF(H21="","",RANK(H21,$H$19:$H$28)) | J21: 0.18 | K21: =IF(H21="","",H21-J21) | L21: =TRIM(IF(N(Calc!M22)>=2,"Discuss together — 2+ levels apart. ","")&IF(COUNTIF(B21:D21,"D")>0,"Ask why it's essential ("&TRIM(IF(B21="D","Mum ","")&IF(C21="D","Dad ","")&IF(D21="D","Me",""))&").",""))
A22: =Survey!C24 -> Beach | B22: =IF(Survey!H24="","–",UPPER(Survey!H24)) -> – | C22: =IF(Survey!I24="","–",UPPER(Survey!I24)) -> – | D22: =IF(Survey!J24="","–",UPPER(Survey!J24)) -> – | E22: =IF(Calc!L23="","",Calc!L23) | F22: =IF(Calc!N23="","",Calc!N23) | H22: =IF(OR(Calc!O23="",SUM(Calc!$O$20:$O$29)=0),"",Calc!O23/SUM(Calc!$O$20:$O$29)) | I22: =IF(H22="","",RANK(H22,$H$19:$H$28)) | J22: 0.1 | K22: =IF(H22="","",H22-J22) | L22: =TRIM(IF(N(Calc!M23)>=2,"Discuss together — 2+ levels apart. ","")&IF(COUNTIF(B22:D22,"D")>0,"Ask why it's essential ("&TRIM(IF(B22="D","Mum ","")&IF(C22="D","Dad ","")&IF(D22="D","Me",""))&").",""))
A23: =Survey!C25 -> Hospital nearby | B23: =IF(Survey!H25="","–",UPPER(Survey!H25)) -> – | C23: =IF(Survey!I25="","–",UPPER(Survey!I25)) -> – | D23: =IF(Survey!J25="","–",UPPER(Survey!J25)) -> – | E23: =IF(Calc!L24="","",Calc!L24) | F23: =IF(Calc!N24="","",Calc!N24) | H23: =IF(OR(Calc!O24="",SUM(Calc!$O$20:$O$29)=0),"",Calc!O24/SUM(Calc!$O$20:$O$29)) | I23: =IF(H23="","",RANK(H23,$H$19:$H$28)) | J23: 0.15 | K23: =IF(H23="","",H23-J23) | L23: =TRIM(IF(N(Calc!M24)>=2,"Discuss together — 2+ levels apart. ","")&IF(COUNTIF(B23:D23,"D")>0,"Ask why it's essential ("&TRIM(IF(B23="D","Mum ","")&IF(C23="D","Dad ","")&IF(D23="D","Me",""))&").",""))
A24: =Survey!C26 -> Train or bus | B24: =IF(Survey!H26="","–",UPPER(Survey!H26)) -> – | C24: =IF(Survey!I26="","–",UPPER(Survey!I26)) -> – | D24: =IF(Survey!J26="","–",UPPER(Survey!J26)) -> – | E24: =IF(Calc!L25="","",Calc!L25) | F24: =IF(Calc!N25="","",Calc!N25) | H24: =IF(OR(Calc!O25="",SUM(Calc!$O$20:$O$29)=0),"",Calc!O25/SUM(Calc!$O$20:$O$29)) | I24: =IF(H24="","",RANK(H24,$H$19:$H$28)) | J24: 0.15 | K24: =IF(H24="","",H24-J24) | L24: =TRIM(IF(N(Calc!M25)>=2,"Discuss together — 2+ levels apart. ","")&IF(COUNTIF(B24:D24,"D")>0,"Ask why it's essential ("&TRIM(IF(B24="D","Mum ","")&IF(C24="D","Dad ","")&IF(D24="D","Me",""))&").",""))
A25: =Survey!C27 -> Shops and doctor nearby | B25: =IF(Survey!H27="","–",UPPER(Survey!H27)) -> – | C25: =IF(Survey!I27="","–",UPPER(Survey!I27)) -> – | D25: =IF(Survey!J27="","–",UPPER(Survey!J27)) -> – | E25: =IF(Calc!L26="","",Calc!L26) | F25: =IF(Calc!N26="","",Calc!N26) | H25: =IF(OR(Calc!O26="",SUM(Calc!$O$20:$O$29)=0),"",Calc!O26/SUM(Calc!$O$20:$O$29)) | I25: =IF(H25="","",RANK(H25,$H$19:$H$28)) | J25: 0.09 | K25: =IF(H25="","",H25-J25) | L25: =TRIM(IF(N(Calc!M26)>=2,"Discuss together — 2+ levels apart. ","")&IF(COUNTIF(B25:D25,"D")>0,"Ask why it's essential ("&TRIM(IF(B25="D","Mum ","")&IF(C25="D","Dad ","")&IF(D25="D","Me",""))&").",""))
A26: =Survey!C28 -> Village character | B26: =IF(Survey!H28="","–",UPPER(Survey!H28)) -> – | C26: =IF(Survey!I28="","–",UPPER(Survey!I28)) -> – | D26: =IF(Survey!J28="","–",UPPER(Survey!J28)) -> – | E26: =IF(Calc!L27="","",Calc!L27) | F26: =IF(Calc!N27="","",Calc!N27) | H26: =IF(OR(Calc!O27="",SUM(Calc!$O$20:$O$29)=0),"",Calc!O27/SUM(Calc!$O$20:$O$29)) | I26: =IF(H26="","",RANK(H26,$H$19:$H$28)) | J26: 0.07 | K26: =IF(H26="","",H26-J26) | L26: =TRIM(IF(N(Calc!M27)>=2,"Discuss together — 2+ levels apart. ","")&IF(COUNTIF(B26:D26,"D")>0,"Ask why it's essential ("&TRIM(IF(B26="D","Mum ","")&IF(C26="D","Dad ","")&IF(D26="D","Me",""))&").",""))
A27: =Survey!C29 -> Price | B27: =IF(Survey!H29="","–",UPPER(Survey!H29)) -> – | C27: =IF(Survey!I29="","–",UPPER(Survey!I29)) -> – | D27: =IF(Survey!J29="","–",UPPER(Survey!J29)) -> – | E27: =IF(Calc!L28="","",Calc!L28) | F27: =IF(Calc!N28="","",Calc!N28) | H27: =IF(OR(Calc!O28="",SUM(Calc!$O$20:$O$29)=0),"",Calc!O28/SUM(Calc!$O$20:$O$29)) | I27: =IF(H27="","",RANK(H27,$H$19:$H$28)) | J27: 0.08 | K27: =IF(H27="","",H27-J27) | L27: =TRIM(IF(N(Calc!M28)>=2,"Discuss together — 2+ levels apart. ","")&IF(COUNTIF(B27:D27,"D")>0,"Ask why it's essential ("&TRIM(IF(B27="D","Mum ","")&IF(C27="D","Dad ","")&IF(D27="D","Me",""))&").",""))
A28: =Survey!C30 -> Easy trip to the city (work, outings) | B28: =IF(Survey!H30="","–",UPPER(Survey!H30)) -> – | C28: =IF(Survey!I30="","–",UPPER(Survey!I30)) -> – | D28: =IF(Survey!J30="","–",UPPER(Survey!J30)) -> – | E28: =IF(Calc!L29="","",Calc!L29) | F28: =IF(Calc!N29="","",Calc!N29) | H28: =IF(OR(Calc!O29="",SUM(Calc!$O$20:$O$29)=0),"",Calc!O29/SUM(Calc!$O$20:$O$29)) | I28: =IF(H28="","",RANK(H28,$H$19:$H$28)) | J28: 0 | K28: =IF(H28="","",H28-J28) | L28: =TRIM(IF(N(Calc!M29)>=2,"Discuss together — 2+ levels apart. ","")&IF(COUNTIF(B28:D28,"D")>0,"Ask why it's essential ("&TRIM(IF(B28="D","Mum ","")&IF(C28="D","Dad ","")&IF(D28="D","Me",""))&").",""))
A29: Total | E29: =SUM(E19:E28) -> 0 | F29: =SUM(F19:F28) -> 0 | H29: =SUM(H19:H28) -> 0 | J29: =SUM(J19:J28) -> 1
A30: Your draft = the weights in 'What the evidence supports'. It had no Glen Waverley or city-trip criterion, so those show 0%.
A32: 3. Forced choices (Q10–13) — trusted over Q15 where they disagree
A33: Question | B33: Picked (by say) | E33: Answers | H33: What it means | K33: Weight moved
A34: Q10 | B34: =IF(Calc!E11="","Not answered",IF(Calc!E11="Split","Split — discuss",IF(Calc!E11="A",Survey!D15,Survey!E15))) -> Not answered | E34: ="Mum "&IF(Survey!H15="","–",UPPER(Survey!H15))&" · Dad "&IF(Survey!I15="","–",UPPER(Survey!I15))&" · Me "&IF(Survey!J15="","–",UPPER(Survey!J15)) -> Mum – · Dad – · Me – | H34: =IF(Calc!E11="A","Nature outweighs being close to Glen Waverley.",IF(Calc!E11="B","Being close to Glen Waverley outweighs nature.",IF(Calc!E11="Split","Raise it together.","—"))) -> — | K34: =IF(OR(Calc!E11="",Calc!E11="Split"),"—",IF(Calc!L11>0,TEXT(Calc!L11*100,"0.0")&" pts to "&INDEX(Calc!$B$20:$B$29,Calc!H11),"None — Q15 already agrees")) -> —
A35: Q11 | B35: =IF(Calc!E12="","Not answered",IF(Calc!E12="Split","Split — discuss",IF(Calc!E12="A",Survey!D16,Survey!E16))) -> Not answered | E35: ="Mum "&IF(Survey!H16="","–",UPPER(Survey!H16))&" · Dad "&IF(Survey!I16="","–",UPPER(Survey!I16))&" · Me "&IF(Survey!J16="","–",UPPER(Survey!J16)) -> Mum – · Dad – · Me – | H35: =IF(Calc!E12="A","Beach outweighs hills and bush.",IF(Calc!E12="B","Hills and bush outweigh the beach; beach can go near zero.",IF(Calc!E12="Split","Raise it together.","—"))) -> — | K35: =IF(OR(Calc!E12="",Calc!E12="Split"),"—",IF(Calc!L12>0,TEXT(Calc!L12*100,"0.0")&" pts to "&INDEX(Calc!$B$20:$B$29,Calc!H12),"None — Q15 already agrees")) -> —
A36: Q12 | B36: =IF(Calc!E13="","Not answered",IF(Calc!E13="Split","Split — discuss",IF(Calc!E13="A",Survey!D17,Survey!E17))) -> Not answered | E36: ="Mum "&IF(Survey!H17="","–",UPPER(Survey!H17))&" · Dad "&IF(Survey!I17="","–",UPPER(Survey!I17))&" · Me "&IF(Survey!J17="","–",UPPER(Survey!J17)) -> Mum – · Dad – · Me – | H36: =IF(Calc!E13="A","A quiet street outweighs walking to shops.",IF(Calc!E13="B","Walking to shops, doctor and station outweighs a quiet street.",IF(Calc!E13="Split","Raise it together.","—"))) -> — | K36: =IF(OR(Calc!E13="",Calc!E13="Split"),"—",IF(Calc!L13>0,TEXT(Calc!L13*100,"0.0")&" pts to "&INDEX(Calc!$B$20:$B$29,Calc!H13),"None — Q15 already agrees")) -> —
A37: Q13 | B37: =IF(Calc!E14="","Not answered",IF(Calc!E14="Split","Split — discuss",IF(Calc!E14="A",Survey!D18,Survey!E18))) -> Not answered | E37: ="Mum "&IF(Survey!H18="","–",UPPER(Survey!H18))&" · Dad "&IF(Survey!I18="","–",UPPER(Survey!I18))&" · Me "&IF(Survey!J18="","–",UPPER(Survey!J18)) -> Mum – · Dad – · Me – | H37: =IF(Calc!E14="A","Community in the suburb outweighs greenery: score community by suburb.",IF(Calc!E14="B","Greenery outweighs community in the suburb: score community by drive time.",IF(Calc!E14="Split","Raise it together.","—"))) -> — | K37: =IF(OR(Calc!E14="",Calc!E14="Split"),"—",IF(Calc!L14>0,TEXT(Calc!L14*100,"0.0")&" pts to "&INDEX(Calc!$B$20:$B$29,Calc!H14),"None — Q15 already agrees")) -> —
A39: 4. What to measure — and what Coorabell tells you
A40: Nature means | B40: =IF((COUNTIF(Survey!H13:J13,"A")+COUNTIF(Survey!H13:J13,"D"))+(COUNTIF(Survey!H13:J13,"B")+COUNTIF(Survey!H13:J13,"C"))=0,"Not answered",IF((COUNTIF(Survey!H13:J13,"B")+COUNTIF(Survey!H13:J13,"C"))>(COUNTIF(Survey!H13:J13,"A")+COUNTIF(Survey!H13:J13,"D")),"Real bush and forest access: reserves, trails and hills within a short drive.",IF((COUNTIF(Survey!H13:J13,"A")+COUNTIF(Survey!H13:J13,"D"))>(COUNTIF(Survey!H13:J13,"B")+COUNTIF(Survey!H13:J13,"C")),"Treed streets, a green outlook and their own garden count as nature.","Mixed — measure both street greenery and bush/trail access."))) -> Not answered
A41: Community means | B41: ="Mum: "&IF(Survey!H14="","–",IFERROR(INDEX(Survey!$D$14:$G$14,MATCH(Survey!H14,'Start here'!$A$19:$A$22,0)),"Other — see notes"))&" · Dad: "&IF(Survey!I14="","–",IFERROR(INDEX(Survey!$D$14:$G$14,MATCH(Survey!I14,'Start here'!$A$19:$A$22,0)),"Other — see notes"))&" · Me: "&IF(Survey!J14="","–",IFERROR(INDEX(Survey!$D$14:$G$14,MATCH(Survey!J14,'Start here'!$A$19:$A$22,0)),"Other — see notes")) -> Mum: – · Dad: – · Me: –
A42: Measure community by | B42: =IF(COUNTA(Survey!H14:J14)=0,"Not answered",TRIM(IF(COUNTIF(Survey!H14:J14,"A")>0,"Drive time to their place of worship. ","")&IF(COUNTIF(Survey!H14:J14,"B")>0,"Distance to Indian grocers and restaurants. ","")&IF(COUNTIF(Survey!H14:J14,"C")>0,"Drive time to language or cultural groups and friends. ","")&IF(COUNTIF(Survey!H14:J14,"D")>0,"Overseas-born share (ABS) is a fair proxy. ","")&IF(Calc!E14="A","Score it by what is inside the suburb (Q13).",IF(Calc!E14="B","Score it by drive time; 20–35 min is fine (Q13).","")))) -> Not answered
A43: Later on (Q14) | B43: =IF((COUNTIF(Survey!H19:J19,"B")+COUNTIF(Survey!H19:J19,"C"))+(COUNTIF(Survey!H19:J19,"A")+COUNTIF(Survey!H19:J19,"D"))=0,"Not answered (optional).",IF((COUNTIF(Survey!H19:J19,"B")+COUNTIF(Survey!H19:J19,"C"))>(COUNTIF(Survey!H19:J19,"A")+COUNTIF(Survey!H19:J19,"D")),"They'd rely on walking or transit later: keep train/bus and walkable shops meaningful even though they drive now."&IF(AND(ISNUMBER(H24),H24<0.05)," Warning: train/bus is only "&TEXT(H24,"0%")&" — consider a tweak upward.",""),IF((COUNTIF(Survey!H19:J19,"A")+COUNTIF(Survey!H19:J19,"D"))>(COUNTIF(Survey!H19:J19,"B")+COUNTIF(Survey!H19:J19,"C")),"They'd stay car-based or move again: train/bus can stay low.","Mixed — discuss."))) -> Not answered (optional).
A44: Coorabell: loved most | B44: ="Mum: "&IF(Survey!H5="","–",IFERROR(INDEX(Survey!$D$5:$G$5,MATCH(Survey!H5,'Start here'!$A$19:$A$22,0)),"Other — see notes"))&" · Dad: "&IF(Survey!I5="","–",IFERROR(INDEX(Survey!$D$5:$G$5,MATCH(Survey!I5,'Start here'!$A$19:$A$22,0)),"Other — see notes"))&" · Me: "&IF(Survey!J5="","–",IFERROR(INDEX(Survey!$D$5:$G$5,MATCH(Survey!J5,'Start here'!$A$19:$A$22,0)),"Other — see notes")) -> Mum: – · Dad: – · Me: –
A45: Coorabell: hardest | B45: ="Mum: "&IF(Survey!H6="","–",IFERROR(INDEX(Survey!$D$6:$G$6,MATCH(Survey!H6,'Start here'!$A$19:$A$22,0)),"Other — see notes"))&" · Dad: "&IF(Survey!I6="","–",IFERROR(INDEX(Survey!$D$6:$G$6,MATCH(Survey!I6,'Start here'!$A$19:$A$22,0)),"Other — see notes"))&" · Me: "&IF(Survey!J6="","–",IFERROR(INDEX(Survey!$D$6:$G$6,MATCH(Survey!J6,'Start here'!$A$19:$A$22,0)),"Other — see notes")) -> Mum: – · Dad: – · Me: –
A46: What that suggests | B46: =IF(COUNTA(Survey!H6:J6)=0,"Not answered",IF(TRIM(IF(COUNTIF(Survey!H6:J6,"A")+COUNTIF(Survey!H6:J6,"C")>0,"Driving or distance to care was hard: lean towards train and hospital access. ","")&IF(COUNTIF(Survey!H6:J6,"B")>0,"Distance from family was hard: supports a firm Glen Waverley limit. ","")&IF(COUNTIF(Survey!H6:J6,"D")>0,"Upkeep was hard: keep the house and garden manageable. ",""))="","See notes.",TRIM(IF(COUNTIF(Survey!H6:J6,"A")+COUNTIF(Survey!H6:J6,"C")>0,"Driving or distance to care was hard: lean towards train and hospital access. ","")&IF(COUNTIF(Survey!H6:J6,"B")>0,"Distance from family was hard: supports a firm Glen Waverley limit. ","")&IF(COUNTIF(Survey!H6:J6,"D")>0,"Upkeep was hard: keep the house and garden manageable. ","")))) -> Not answered
...

Sheet Suburb scorecard
A1: Suburb scorecard — weights and filters flow in from Results
A2: Yellow = enter. Scores 0–10 (10 = best for them). Prices prefilled from 'What the evidence supports' (house); replace with the price of the home they'd actually need.
A4: Budget (incl. costs) | B4: =Results!B8 -> Not answered | C4: Max to Glen Waverley | D4: =Results!B9 -> Not answered | E4: Max to ED | F4: =Results!B10 -> Not answered | G4: Est. costs | H4: ='Start here'!$B$25 -> 0.06
G6: Final weight → | H6: =Results!H19 | I6: =Results!H20 | J6: =Results!H21 | K6: =Results!H22 | L6: =Results!H23 | M6: =Results!H24 | N6: =Results!H25 | O6: =Results!H26 | P6: =Results!H27 | Q6: =Results!H28
A7: Suburb | B7: Price (house) | C7: Price basis | D7: Price + est. costs | E7: Drive to Glen Waverley (min) | F7: Drive to nearest ED (min) | G7: Filters | H7: =Results!A19 -> Nature and scenery | I7: =Results!A20 -> Near family in Glen Waverley | J7: =Results!A21 -> Indian/South Asian community | K7: =Results!A22 -> Beach | L7: =Results!A23 -> Hospital nearby | M7: =Results!A24 -> Train or bus | N7: =Results!A25 -> Shops and doctor nearby | O7: =Results!A26 -> Village character | P7: =Results!A27 -> Price | Q7: =Results!A28 -> Easy trip to the city (work, outings) | R7: Scores entered | S7: Weighted score (0–10) | T7: Rank (passing) | U7: Overseas-born % (2021)
A8: Blackburn | B8: 1600000 | C8: Sale median, rolling 12m | D8: =IF(B8="","",B8*(1+$H$4)) -> 1696000 | G8: =IF(A8="","",IF(OR(AND(ISNUMBER($B$4),ISNUMBER(D8),D8>$B$4),AND(ISNUMBER($D$4),ISNUMBER(E8),E8>$D$4),AND(ISNUMBER($F$4),ISNUMBER(F8),F8>$F$4)),"Fails: "&_xlfn.TEXTJOIN(", ",TRUE(),IF(AND(ISNUMBER($B$4),ISNUMBER(D8),D8>$B$4),"budget",""),IF(AND(ISNUMBER($D$4),ISNUMBER(E8),E8>$D$4),"Glen Waverley drive",""),IF(AND(ISNUMBER($F$4),ISNUMBER(F8),F8>$F$4),"hospital drive","")),IF(OR(B8="",E8="",F8=""),"Need data","Pass"))) -> Need data | R8: =IF(A8="","",COUNT(H8:Q8)&"/10") -> 0/10 | S8: =IF(OR(A8="",COUNT(H8:Q8)<10,COUNT($H$6:$Q$6)<10),"",SUMPRODUCT(H8:Q8,$H$6:$Q$6)) | T8: =IF(AND(G8="Pass",ISNUMBER(S8)),SUMPRODUCT(($G$8:$G$21="Pass")*ISNUMBER($S$8:$S$21)*($S$8:$S$21>S8))+1,"") | U8: 0.324
A9: Ringwood | B9: 1045000 | C9: Sale median, rolling 12m | D9: =IF(B9="","",B9*(1+$H$4)) -> 1107700 | G9: =IF(A9="","",IF(OR(AND(ISNUMBER($B$4),ISNUMBER(D9),D9>$B$4),AND(ISNUMBER($D$4),ISNUMBER(E9),E9>$D$4),AND(ISNUMBER($F$4),ISNUMBER(F9),F9>$F$4)),"Fails: "&_xlfn.TEXTJOIN(", ",TRUE(),IF(AND(ISNUMBER($B$4),ISNUMBER(D9),D9>$B$4),"budget",""),IF(AND(ISNUMBER($D$4),ISNUMBER(E9),E9>$D$4),"Glen Waverley drive",""),IF(AND(ISNUMBER($F$4),ISNUMBER(F9),F9>$F$4),"hospital drive","")),IF(OR(B9="",E9="",F9=""),"Need data","Pass"))) -> Need data | R9: =IF(A9="","",COUNT(H9:Q9)&"/10") -> 0/10 | S9: =IF(OR(A9="",COUNT(H9:Q9)<10,COUNT($H$6:$Q$6)<10),"",SUMPRODUCT(H9:Q9,$H$6:$Q$6)) | T9: =IF(AND(G9="Pass",ISNUMBER(S9)),SUMPRODUCT(($G$8:$G$21="Pass")*ISNUMBER($S$8:$S$21)*($S$8:$S$21>S9))+1,"") | U9: 0.357
A10: Heidelberg | B10: 1452000 | C10: Sale median, rolling 12m (35 sales) | D10: =IF(B10="","",B10*(1+$H$4)) -> 1539120 | G10: =IF(A10="","",IF(OR(AND(ISNUMBER($B$4),ISNUMBER(D10),D10>$B$4),AND(ISNUMBER($D$4),ISNUMBER(E10),E10>$D$4),AND(ISNUMBER($F$4),ISNUMBER(F10),F10>$F$4)),"Fails: "&_xlfn.TEXTJOIN(", ",TRUE(),IF(AND(ISNUMBER($B$4),ISNUMBER(D10),D10>$B$4),"budget",""),IF(AND(ISNUMBER($D$4),ISNUMBER(E10),E10>$D$4),"Glen Waverley drive",""),IF(AND(ISNUMBER($F$4),ISNUMBER(F10),F10>$F$4),"hospital drive","")),IF(OR(B10="",E10="",F10=""),"Need data","Pass"))) -> Need data | R10: =IF(A10="","",COUNT(H10:Q10)&"/10") -> 0/10 | S10: =IF(OR(A10="",COUNT(H10:Q10)<10,COUNT($H$6:$Q$6)<10),"",SUMPRODUCT(H10:Q10,$H$6:$Q$6)) | T10: =IF(AND(G10="Pass",ISNUMBER(S10)),SUMPRODUCT(($G$8:$G$21="Pass")*ISNUMBER($S$8:$S$21)*($S$8:$S$21>S10))+1,"") | U10: 0.281
A11: Eltham | B11: 1273000 | C11: Sale median, rolling 12m | D11: =IF(B11="","",B11*(1+$H$4)) -> 1349380 | G11: =IF(A11="","",IF(OR(AND(ISNUMBER($B$4),ISNUMBER(D11),D11>$B$4),AND(ISNUMBER($D$4),ISNUMBER(E11),E11>$D$4),AND(ISNUMBER($F$4),ISNUMBER(F11),F11>$F$4)),"Fails: "&_xlfn.TEXTJOIN(", ",TRUE(),IF(AND(ISNUMBER($B$4),ISNUMBER(D11),D11>$B$4),"budget",""),IF(AND(ISNUMBER($D$4),ISNUMBER(E11),E11>$D$4),"Glen Waverley drive",""),IF(AND(ISNUMBER($F$4),ISNUMBER(F11),F11>$F$4),"hospital drive","")),IF(OR(B11="",E11="",F11=""),"Need data","Pass"))) -> Need data | R11: =IF(A11="","",COUNT(H11:Q11)&"/10") -> 0/10 | S11: =IF(OR(A11="",COUNT(H11:Q11)<10,COUNT($H$6:$Q$6)<10),"",SUMPRODUCT(H11:Q11,$H$6:$Q$6)) | T11: =IF(AND(G11="Pass",ISNUMBER(S11)),SUMPRODUCT(($G$8:$G$21="Pass")*ISNUMBER($S$8:$S$21)*($S$8:$S$21>S11))+1,"") | U11: 0.185
A12: Upper Ferntree Gully | B12: 872133 | C12: AVM estimate (30 Sep 2026), not a sale median | D12: =IF(B12="","",B12*(1+$H$4)) -> 924460.98 | G12: =IF(A12="","",IF(OR(AND(ISNUMBER($B$4),ISNUMBER(D12),D12>$B$4),AND(ISNUMBER($D$4),ISNUMBER(E12),E12>$D$4),AND(ISNUMBER($F$4),ISNUMBER(F12),F12>$F$4)),"Fails: "&_xlfn.TEXTJOIN(", ",TRUE(),IF(AND(ISNUMBER($B$4),ISNUMBER(D12),D12>$B$4),"budget",""),IF(AND(ISNUMBER($D$4),ISNUMBER(E12),E12>$D$4),"Glen Waverley drive",""),IF(AND(ISNUMBER($F$4),ISNUMBER(F12),F12>$F$4),"hospital drive","")),IF(OR(B12="",E12="",F12=""),"Need data","Pass"))) -> Need data | R12: =IF(A12="","",COUNT(H12:Q12)&"/10") -> 0/10 | S12: =IF(OR(A12="",COUNT(H12:Q12)<10,COUNT($H$6:$Q$6)<10),"",SUMPRODUCT(H12:Q12,$H$6:$Q$6)) | T12: =IF(AND(G12="Pass",ISNUMBER(S12)),SUMPRODUCT(($G$8:$G$21="Pass")*ISNUMBER($S$8:$S$21)*($S$8:$S$21>S12))+1,"") | U12: 0.192
A13: Glen Waverley | B13: 1763500 | C13: Sale median, rolling 12m | D13: =IF(B13="","",B13*(1+$H$4)) -> 1869310 | G13: =IF(A13="","",IF(OR(AND(ISNUMBER($B$4),ISNUMBER(D13),D13>$B$4),AND(ISNUMBER($D$4),ISNUMBER(E13),E13>$D$4),AND(ISNUMBER($F$4),ISNUMBER(F13),F13>$F$4)),"Fails: "&_xlfn.TEXTJOIN(", ",TRUE(),IF(AND(ISNUMBER($B$4),ISNUMBER(D13),D13>$B$4),"budget",""),IF(AND(ISNUMBER($D$4),ISNUMBER(E13),E13>$D$4),"Glen Waverley drive",""),IF(AND(ISNUMBER($F$4),ISNUMBER(F13),F13>$F$4),"hospital drive","")),IF(OR(B13="",E13="",F13=""),"Need data","Pass"))) -> Need data | R13: =IF(A13="","",COUNT(H13:Q13)&"/10") -> 0/10 | S13: =IF(OR(A13="",COUNT(H13:Q13)<10,COUNT($H$6:$Q$6)<10),"",SUMPRODUCT(H13:Q13,$H$6:$Q$6)) | T13: =IF(AND(G13="Pass",ISNUMBER(S13)),SUMPRODUCT(($G$8:$G$21="Pass")*ISNUMBER($S$8:$S$21)*($S$8:$S$21>S13))+1,"") | U13: 0.587
A14: Mentone | B14: 1497099 | C14: Sale median (Aussie); Woodards shows $1.30m | D14: =IF(B14="","",B14*(1+$H$4)) -> 1586924.9 | G14: =IF(A14="","",IF(OR(AND(ISNUMBER($B$4),ISNUMBER(D14),D14>$B$4),AND(ISNUMBER($D$4),ISNUMBER(E14),E14>$D$4),AND(ISNUMBER($F$4),ISNUMBER(F14),F14>$F$4)),"Fails: "&_xlfn.TEXTJOIN(", ",TRUE(),IF(AND(ISNUMBER($B$4),ISNUMBER(D14),D14>$B$4),"budget",""),IF(AND(ISNUMBER($D$4),ISNUMBER(E14),E14>$D$4),"Glen Waverley drive",""),IF(AND(ISNUMBER($F$4),ISNUMBER(F14),F14>$F$4),"hospital drive","")),IF(OR(B14="",E14="",F14=""),"Need data","Pass"))) -> Need data | R14: =IF(A14="","",COUNT(H14:Q14)&"/10") -> 0/10 | S14: =IF(OR(A14="",COUNT(H14:Q14)<10,COUNT($H$6:$Q$6)<10),"",SUMPRODUCT(H14:Q14,$H$6:$Q$6)) | T14: =IF(AND(G14="Pass",ISNUMBER(S14)),SUMPRODUCT(($G$8:$G$21="Pass")*ISNUMBER($S$8:$S$21)*($S$8:$S$21>S14))+1,"") | U14: 0.288
A15: Frankston | B15: 834296 | C15: Sale median, rolling 12m | D15: =IF(B15="","",B15*(1+$H$4)) -> 884353.76 | G15: =IF(A15="","",IF(OR(AND(ISNUMBER($B$4),ISNUMBER(D15),D15>$B$4),AND(ISNUMBER($D$4),ISNUMBER(E15),E15>$D$4),AND(ISNUMBER($F$4),ISNUMBER(F15),F15>$F$4)),"Fails: "&_xlfn.TEXTJOIN(", ",TRUE(),IF(AND(ISNUMBER($B$4),ISNUMBER(D15),D15>$B$4),"budget",""),IF(AND(ISNUMBER($D$4),ISNUMBER(E15),E15>$D$4),"Glen Waverley drive",""),IF(AND(ISNUMBER($F$4),ISNUMBER(F15),F15>$F$4),"hospital drive","")),IF(OR(B15="",E15="",F15=""),"Need data","Pass"))) -> Need data | R15: =IF(A15="","",COUNT(H15:Q15)&"/10") -> 0/10 | S15: =IF(OR(A15="",COUNT(H15:Q15)<10,COUNT($H$6:$Q$6)<10),"",SUMPRODUCT(H15:Q15,$H$6:$Q$6)) | T15: =IF(AND(G15="Pass",ISNUMBER(S15)),SUMPRODUCT(($G$8:$G$21="Pass")*ISNUMBER($S$8:$S$21)*($S$8:$S$21>S15))+1,"") | U15: 0.225
A16: Altona | B16: 1155073 | C16: AVM estimate (31 Aug 2026), not a sale median | D16: =IF(B16="","",B16*(1+$H$4)) -> 1224377.4 | G16: =IF(A16="","",IF(OR(AND(ISNUMBER($B$4),ISNUMBER(D16),D16>$B$4),AND(ISNUMBER($D$4),ISNUMBER(E16),E16>$D$4),AND(ISNUMBER($F$4),ISNUMBER(F16),F16>$F$4)),"Fails: "&_xlfn.TEXTJOIN(", ",TRUE(),IF(AND(ISNUMBER($B$4),ISNUMBER(D16),D16>$B$4),"budget",""),IF(AND(ISNUMBER($D$4),ISNUMBER(E16),E16>$D$4),"Glen Waverley drive",""),IF(AND(ISNUMBER($F$4),ISNUMBER(F16),F16>$F$4),"hospital drive","")),IF(OR(B16="",E16="",F16=""),"Need data","Pass"))) -> Need data | R16: =IF(A16="","",COUNT(H16:Q16)&"/10") -> 0/10 | S16: =IF(OR(A16="",COUNT(H16:Q16)<10,COUNT($H$6:$Q$6)<10),"",SUMPRODUCT(H16:Q16,$H$6:$Q$6)) | T16: =IF(AND(G16="Pass",ISNUMBER(S16)),SUMPRODUCT(($G$8:$G$21="Pass")*ISNUMBER($S$8:$S$21)*($S$8:$S$21>S16))+1,"") | U16: 0.283
A17: Williamstown | B17: 1642163 | C17: AVM estimate (30 Sep 2026), not a sale median | D17: =IF(B17="","",B17*(1+$H$4)) -> 1740692.8 | G17: =IF(A17="","",IF(OR(AND(ISNUMBER($B$4),ISNUMBER(D17),D17>$B$4),AND(ISNUMBER($D$4),ISNUMBER(E17),E17>$D$4),AND(ISNUMBER($F$4),ISNUMBER(F17),F17>$F$4)),"Fails: "&_xlfn.TEXTJOIN(", ",TRUE(),IF(AND(ISNUMBER($B$4),ISNUMBER(D17),D17>$B$4),"budget",""),IF(AND(ISNUMBER($D$4),ISNUMBER(E17),E17>$D$4),"Glen Waverley drive",""),IF(AND(ISNUMBER($F$4),ISNUMBER(F17),F17>$F$4),"hospital drive","")),IF(OR(B17="",E17="",F17=""),"Need data","Pass"))) -> Need data | R17: =IF(A17="","",COUNT(H17:Q17)&"/10") -> 0/10 | S17: =IF(OR(A17="",COUNT(H17:Q17)<10,COUNT($H$6:$Q$6)<10),"",SUMPRODUCT(H17:Q17,$H$6:$Q$6)) | T17: =IF(AND(G17="Pass",ISNUMBER(S17)),SUMPRODUCT(($G$8:$G$21="Pass")*ISNUMBER($S$8:$S$21)*($S$8:$S$21>S17))+1,"") | U17: 0.226
D18: =IF(B18="","",B18*(1+$H$4)) | G18: =IF(A18="","",IF(OR(AND(ISNUMBER($B$4),ISNUMBER(D18),D18>$B$4),AND(ISNUMBER($D$4),ISNUMBER(E18),E18>$D$4),AND(ISNUMBER($F$4),ISNUMBER(F18),F18>$F$4)),"Fails: "&_xlfn.TEXTJOIN(", ",TRUE(),IF(AND(ISNUMBER($B$4),ISNUMBER(D18),D18>$B$4),"budget",""),IF(AND(ISNUMBER($D$4),ISNUMBER(E18),E18>$D$4),"Glen Waverley drive",""),IF(AND(ISNUMBER($F$4),ISNUMBER(F18),F18>$F$4),"hospital drive","")),IF(OR(B18="",E18="",F18=""),"Need data","Pass"))) | R18: =IF(A18="","",COUNT(H18:Q18)&"/10") | S18: =IF(OR(A18="",COUNT(H18:Q18)<10,COUNT($H$6:$Q$6)<10),"",SUMPRODUCT(H18:Q18,$H$6:$Q$6)) | T18: =IF(AND(G18="Pass",ISNUMBER(S18)),SUMPRODUCT(($G$8:$G$21="Pass")*ISNUMBER($S$8:$S$21)*($S$8:$S$21>S18))+1,"")
D19: =IF(B19="","",B19*(1+$H$4)) | G19: =IF(A19="","",IF(OR(AND(ISNUMBER($B$4),ISNUMBER(D19),D19>$B$4),AND(ISNUMBER($D$4),ISNUMBER(E19),E19>$D$4),AND(ISNUMBER($F$4),ISNUMBER(F19),F19>$F$4)),"Fails: "&_xlfn.TEXTJOIN(", ",TRUE(),IF(AND(ISNUMBER($B$4),ISNUMBER(D19),D19>$B$4),"budget",""),IF(AND(ISNUMBER($D$4),ISNUMBER(E19),E19>$D$4),"Glen Waverley drive",""),IF(AND(ISNUMBER($F$4),ISNUMBER(F19),F19>$F$4),"hospital drive","")),IF(OR(B19="",E19="",F19=""),"Need data","Pass"))) | R19: =IF(A19="","",COUNT(H19:Q19)&"/10") | S19: =IF(OR(A19="",COUNT(H19:Q19)<10,COUNT($H$6:$Q$6)<10),"",SUMPRODUCT(H19:Q19,$H$6:$Q$6)) | T19: =IF(AND(G19="Pass",ISNUMBER(S19)),SUMPRODUCT(($G$8:$G$21="Pass")*ISNUMBER($S$8:$S$21)*($S$8:$S$21>S19))+1,"")
D20: =IF(B20="","",B20*(1+$H$4)) | G20: =IF(A20="","",IF(OR(AND(ISNUMBER($B$4),ISNUMBER(D20),D20>$B$4),AND(ISNUMBER($D$4),ISNUMBER(E20),E20>$D$4),AND(ISNUMBER($F$4),ISNUMBER(F20),F20>$F$4)),"Fails: "&_xlfn.TEXTJOIN(", ",TRUE(),IF(AND(ISNUMBER($B$4),ISNUMBER(D20),D20>$B$4),"budget",""),IF(AND(ISNUMBER($D$4),ISNUMBER(E20),E20>$D$4),"Glen Waverley drive",""),IF(AND(ISNUMBER($F$4),ISNUMBER(F20),F20>$F$4),"hospital drive","")),IF(OR(B20="",E20="",F20=""),"Need data","Pass"))) | R20: =IF(A20="","",COUNT(H20:Q20)&"/10") | S20: =IF(OR(A20="",COUNT(H20:Q20)<10,COUNT($H$6:$Q$6)<10),"",SUMPRODUCT(H20:Q20,$H$6:$Q$6)) | T20: =IF(AND(G20="Pass",ISNUMBER(S20)),SUMPRODUCT(($G$8:$G$21="Pass")*ISNUMBER($S$8:$S$21)*($S$8:$S$21>S20))+1,"")
D21: =IF(B21="","",B21*(1+$H$4)) | G21: =IF(A21="","",IF(OR(AND(ISNUMBER($B$4),ISNUMBER(D21),D21>$B$4),AND(ISNUMBER($D$4),ISNUMBER(E21),E21>$D$4),AND(ISNUMBER($F$4),ISNUMBER(F21),F21>$F$4)),"Fails: "&_xlfn.TEXTJOIN(", ",TRUE(),IF(AND(ISNUMBER($B$4),ISNUMBER(D21),D21>$B$4),"budget",""),IF(AND(ISNUMBER($D$4),ISNUMBER(E21),E21>$D$4),"Glen Waverley drive",""),IF(AND(ISNUMBER($F$4),ISNUMBER(F21),F21>$F$4),"hospital drive","")),IF(OR(B21="",E21="",F21=""),"Need data","Pass"))) | R21: =IF(A21="","",COUNT(H21:Q21)&"/10") | S21: =IF(OR(A21="",COUNT(H21:Q21)<10,COUNT($H$6:$Q$6)<10),"",SUMPRODUCT(H21:Q21,$H$6:$Q$6)) | T21: =IF(AND(G21="Pass",ISNUMBER(S21)),SUMPRODUCT(($G$8:$G$21="Pass")*ISNUMBER($S$8:$S$21)*($S$8:$S$21>S21))+1,"")
A23: Sources: prices and overseas-born shares from 'What the evidence supports' (research date 25 Oct 2026); ABS Census 2021 General Community Profiles. Blank rows are for reserve suburbs (e.g. Upwey, Belgrave, Box Hill, Rosanna).

Sheet Calc
A1: Calc — workings (no edits needed)
A2: Filter | B2: Mum | C2: Dad | D2: Me | E2: Strictest | R2: Budget | U2: GW drive | X2: ED drive | AA2: Stairs level | AD2: Space level
A3: Budget ceiling incl. costs | B3: =IF(Survey!H7="","",IFERROR(INDEX($S$3:$S$6,MATCH(Survey!H7,$R$3:$R$6,0)),"")) | C3: =IF(Survey!I7="","",IFERROR(INDEX($S$3:$S$6,MATCH(Survey!I7,$R$3:$R$6,0)),"")) | D3: =IF(Survey!J7="","",IFERROR(INDEX($S$3:$S$6,MATCH(Survey!J7,$R$3:$R$6,0)),"")) | E3: =IF(COUNT(B3:D3)>0,MIN(B3:D3),IF(COUNTIF(B3:D3,"No cap")>0,"No cap","Not answered")) -> Not answered | R3: A | S3: 1000000 | U3: A | V3: 15 | X3: A | Y3: 10 | AA3: A | AB3: 1 | AD3: A | AE3: 1
A4: Max drive to Glen Waverley (min) | B4: =IF(Survey!H8="","",IFERROR(INDEX($V$3:$V$6,MATCH(Survey!H8,$U$3:$U$6,0)),"")) | C4: =IF(Survey!I8="","",IFERROR(INDEX($V$3:$V$6,MATCH(Survey!I8,$U$3:$U$6,0)),"")) | D4: =IF(Survey!J8="","",IFERROR(INDEX($V$3:$V$6,MATCH(Survey!J8,$U$3:$U$6,0)),"")) | E4: =IF(COUNT(B4:D4)>0,MIN(B4:D4),"Not answered") -> Not answered | R4: B | S4: 1250000 | U4: B | V4: 25 | X4: B | Y4: 20 | AA4: B | AB4: 2 | AD4: B | AE4: 2
A5: Max drive to ED (min) | B5: =IF(Survey!H9="","",IFERROR(INDEX($Y$3:$Y$6,MATCH(Survey!H9,$X$3:$X$6,0)),"")) | C5: =IF(Survey!I9="","",IFERROR(INDEX($Y$3:$Y$6,MATCH(Survey!I9,$X$3:$X$6,0)),"")) | D5: =IF(Survey!J9="","",IFERROR(INDEX($Y$3:$Y$6,MATCH(Survey!J9,$X$3:$X$6,0)),"")) | E5: =IF(COUNT(B5:D5)>0,MIN(B5:D5),IF(COUNTIF(B5:D5,"No limit")>0,"No limit","Not answered")) -> Not answered | R5: C | S5: 1500000 | U5: C | V5: 35 | X5: C | Y5: 30 | AA5: C | AB5: 3 | AD5: C | AE5: 3
A6: Stairs level (1 = strictest) | B6: =IF(Survey!H10="","",IFERROR(INDEX($AB$3:$AB$5,MATCH(Survey!H10,$AA$3:$AA$5,0)),"")) | C6: =IF(Survey!I10="","",IFERROR(INDEX($AB$3:$AB$5,MATCH(Survey!I10,$AA$3:$AA$5,0)),"")) | D6: =IF(Survey!J10="","",IFERROR(INDEX($AB$3:$AB$5,MATCH(Survey!J10,$AA$3:$AA$5,0)),"")) | E6: =IF(COUNT(B6:D6)>0,MIN(B6:D6),"Not answered") -> Not answered | R6: D | S6: No cap | U6: D | V6: 45 | X6: D | Y6: No limit | AD6: D | AE6: 4
A7: Space level (4 = most space) | B7: =IF(Survey!H12="","",IFERROR(INDEX($AE$3:$AE$6,MATCH(Survey!H12,$AD$3:$AD$6,0)),"")) | C7: =IF(Survey!I12="","",IFERROR(INDEX($AE$3:$AE$6,MATCH(Survey!I12,$AD$3:$AD$6,0)),"")) | D7: =IF(Survey!J12="","",IFERROR(INDEX($AE$3:$AE$6,MATCH(Survey!J12,$AD$3:$AD$6,0)),"")) | E7: =IF(COUNT(B7:D7)>0,MAX(B7:D7),"Not answered") -> Not answered
A10: Question | B10: Survey row | C10: A votes | D10: B votes | E10: Result | F10: A-side item | G10: B-side item | H10: Winner | I10: Loser | J10: Winner wt | K10: Loser wt | L10: Transfer
A11: Q10 | B11: 15 | C11: =(Survey!H15="A")*'Start here'!$B$14+(Survey!I15="A")*'Start here'!$B$15+(Survey!J15="A")*'Start here'!$B$16 -> 0 | D11: =(Survey!H15="B")*'Start here'!$B$14+(Survey!I15="B")*'Start here'!$B$15+(Survey!J15="B")*'Start here'!$B$16 -> 0 | E11: =IF(C11+D11=0,"",IF(C11>D11,"A",IF(D11>C11,"B","Split"))) | F11: 1 | G11: 2 | H11: =IF(E11="A",F11,IF(E11="B",G11,"")) | I11: =IF(E11="A",G11,IF(E11="B",F11,"")) | J11: =IF(H11="","",INDEX($L$20:$L$29,H11)) | K11: =IF(I11="","",INDEX($L$20:$L$29,I11)) | L11: =IF(OR(H11="",NOT(ISNUMBER(J11)),NOT(ISNUMBER(K11))),0,IF(J11<K11+'Start here'!$B$26,MIN(K11,(K11-J11+'Start here'!$B$26)/2),0)) -> 0
A12: Q11 | B12: 16 | C12: =(Survey!H16="A")*'Start here'!$B$14+(Survey!I16="A")*'Start here'!$B$15+(Survey!J16="A")*'Start here'!$B$16 -> 0 | D12: =(Survey!H16="B")*'Start here'!$B$14+(Survey!I16="B")*'Start here'!$B$15+(Survey!J16="B")*'Start here'!$B$16 -> 0 | E12: =IF(C12+D12=0,"",IF(C12>D12,"A",IF(D12>C12,"B","Split"))) | F12: 4 | G12: 1 | H12: =IF(E12="A",F12,IF(E12="B",G12,"")) | I12: =IF(E12="A",G12,IF(E12="B",F12,"")) | J12: =IF(H12="","",INDEX($L$20:$L$29,H12)) | K12: =IF(I12="","",INDEX($L$20:$L$29,I12)) | L12: =IF(OR(H12="",NOT(ISNUMBER(J12)),NOT(ISNUMBER(K12))),0,IF(J12<K12+'Start here'!$B$26,MIN(K12,(K12-J12+'Start here'!$B$26)/2),0)) -> 0
A13: Q12 | B13: 17 | C13: =(Survey!H17="A")*'Start here'!$B$14+(Survey!I17="A")*'Start here'!$B$15+(Survey!J17="A")*'Start here'!$B$16 -> 0 | D13: =(Survey!H17="B")*'Start here'!$B$14+(Survey!I17="B")*'Start here'!$B$15+(Survey!J17="B")*'Start here'!$B$16 -> 0 | E13: =IF(C13+D13=0,"",IF(C13>D13,"A",IF(D13>C13,"B","Split"))) | F13: 8 | G13: 7 | H13: =IF(E13="A",F13,IF(E13="B",G13,"")) | I13: =IF(E13="A",G13,IF(E13="B",F13,"")) | J13: =IF(H13="","",INDEX($L$20:$L$29,H13)) | K13: =IF(I13="","",INDEX($L$20:$L$29,I13)) | L13: =IF(OR(H13="",NOT(ISNUMBER(J13)),NOT(ISNUMBER(K13))),0,IF(J13<K13+'Start here'!$B$26,MIN(K13,(K13-J13+'Start here'!$B$26)/2),0)) -> 0
A14: Q13 | B14: 18 | C14: =(Survey!H18="A")*'Start here'!$B$14+(Survey!I18="A")*'Start here'!$B$15+(Survey!J18="A")*'Start here'!$B$16 -> 0 | D14: =(Survey!H18="B")*'Start here'!$B$14+(Survey!I18="B")*'Start here'!$B$15+(Survey!J18="B")*'Start here'!$B$16 -> 0 | E14: =IF(C14+D14=0,"",IF(C14>D14,"A",IF(D14>C14,"B","Split"))) | F14: 3 | G14: 1 | H14: =IF(E14="A",F14,IF(E14="B",G14,"")) | I14: =IF(E14="A",G14,IF(E14="B",F14,"")) | J14: =IF(H14="","",INDEX($L$20:$L$29,H14)) | K14: =IF(I14="","",INDEX($L$20:$L$29,I14)) | L14: =IF(OR(H14="",NOT(ISNUMBER(J14)),NOT(ISNUMBER(K14))),0,IF(J14<K14+'Start here'!$B$26,MIN(K14,(K14-J14+'Start here'!$B$26)/2),0)) -> 0
A19: # | B19: Priority | C19: Mum score | D19: Dad score | E19: Me score | F19: Mum level | G19: Dad level | H19: Me level | I19: Mum wt | J19: Dad wt | K19: Me wt | L19: Combined | M19: Levels apart | N19: Correction | O19: Raw final | P19: Abs change | Q19: Discuss text
A20: 1 | B20: =Survey!C21 -> Nature and scenery | C20: =IF(Survey!H21="","",IFERROR(INDEX('Start here'!$C$19:$C$22,MATCH(Survey!H21,'Start here'!$A$19:$A$22,0)),"")) | D20: =IF(Survey!I21="","",IFERROR(INDEX('Start here'!$C$19:$C$22,MATCH(Survey!I21,'Start here'!$A$19:$A$22,0)),"")) | E20: =IF(Survey!J21="","",IFERROR(INDEX('Start here'!$C$19:$C$22,MATCH(Survey!J21,'Start here'!$A$19:$A$22,0)),"")) | F20: =IF(Survey!H21="","",IFERROR(MATCH(Survey!H21,'Start here'!$A$19:$A$22,0),"")) | G20: =IF(Survey!I21="","",IFERROR(MATCH(Survey!I21,'Start here'!$A$19:$A$22,0),"")) | H20: =IF(Survey!J21="","",IFERROR(MATCH(Survey!J21,'Start here'!$A$19:$A$22,0),"")) | I20: =IF(AND(ISNUMBER(C20),C$31>0),C20/C$31,"") | J20: =IF(AND(ISNUMBER(D20),D$31>0),D20/D$31,"") | K20: =IF(AND(ISNUMBER(E20),E$31>0),E20/E$31,"") | L20: =IF($L$31=0,"",(IF(ISNUMBER(I20),'Start here'!$B$14*I20,0)+IF(ISNUMBER(J20),'Start here'!$B$15*J20,0)+IF(ISNUMBER(K20),'Start here'!$B$16*K20,0))/$L$31) | M20: =IF(COUNT(F20:H20)>=2,MAX(F20:H20)-MIN(F20:H20),"") | N20: =IF(L20="","",SUMIF($H$11:$H$14,A20,$L$11:$L$14)-SUMIF($I$11:$I$14,A20,$L$11:$L$14)) | O20: =IF(L20="","",MAX(0,L20+N20+N(Results!G19)/100)) | P20: =IF(Results!K19="","",ABS(Results!K19)+A20/1000000000) | Q20: =IF(N(M20)>=2,"Q15 "&B20&" — 2+ levels apart ("&"Mum "&IF(Survey!H21="","–",UPPER(Survey!H21))&", Dad "&IF(Survey!I21="","–",UPPER(Survey!I21))&", Me "&IF(Survey!J21="","–",UPPER(Survey!J21))&")","")
A21: 2 | B21: =Survey!C22 -> Near family in Glen Waverley | C21: =IF(Survey!H22="","",IFERROR(INDEX('Start here'!$C$19:$C$22,MATCH(Survey!H22,'Start here'!$A$19:$A$22,0)),"")) | D21: =IF(Survey!I22="","",IFERROR(INDEX('Start here'!$C$19:$C$22,MATCH(Survey!I22,'Start here'!$A$19:$A$22,0)),"")) | E21: =IF(Survey!J22="","",IFERROR(INDEX('Start here'!$C$19:$C$22,MATCH(Survey!J22,'Start here'!$A$19:$A$22,0)),"")) | F21: =IF(Survey!H22="","",IFERROR(MATCH(Survey!H22,'Start here'!$A$19:$A$22,0),"")) | G21: =IF(Survey!I22="","",IFERROR(MATCH(Survey!I22,'Start here'!$A$19:$A$22,0),"")) | H21: =IF(Survey!J22="","",IFERROR(MATCH(Survey!J22,'Start here'!$A$19:$A$22,0),"")) | I21: =IF(AND(ISNUMBER(C21),C$31>0),C21/C$31,"") | J21: =IF(AND(ISNUMBER(D21),D$31>0),D21/D$31,"") | K21: =IF(AND(ISNUMBER(E21),E$31>0),E21/E$31,"") | L21: =IF($L$31=0,"",(IF(ISNUMBER(I21),'Start here'!$B$14*I21,0)+IF(ISNUMBER(J21),'Start here'!$B$15*J21,0)+IF(ISNUMBER(K21),'Start here'!$B$16*K21,0))/$L$31) | M21: =IF(COUNT(F21:H21)>=2,MAX(F21:H21)-MIN(F21:H21),"") | N21: =IF(L21="","",SUMIF($H$11:$H$14,A21,$L$11:$L$14)-SUMIF($I$11:$I$14,A21,$L$11:$L$14)) | O21: =IF(L21="","",MAX(0,L21+N21+N(Results!G20)/100)) | P21: =IF(Results!K20="","",ABS(Results!K20)+A21/1000000000) | Q21: =IF(N(M21)>=2,"Q15 "&B21&" — 2+ levels apart ("&"Mum "&IF(Survey!H22="","–",UPPER(Survey!H22))&", Dad "&IF(Survey!I22="","–",UPPER(Survey!I22))&", Me "&IF(Survey!J22="","–",UPPER(Survey!J22))&")","")
A22: 3 | B22: =Survey!C23 -> Indian/South Asian community | C22: =IF(Survey!H23="","",IFERROR(INDEX('Start here'!$C$19:$C$22,MATCH(Survey!H23,'Start here'!$A$19:$A$22,0)),"")) | D22: =IF(Survey!I23="","",IFERROR(INDEX('Start here'!$C$19:$C$22,MATCH(Survey!I23,'Start here'!$A$19:$A$22,0)),"")) | E22: =IF(Survey!J23="","",IFERROR(INDEX('Start here'!$C$19:$C$22,MATCH(Survey!J23,'Start here'!$A$19:$A$22,0)),"")) | F22: =IF(Survey!H23="","",IFERROR(MATCH(Survey!H23,'Start here'!$A$19:$A$22,0),"")) | G22: =IF(Survey!I23="","",IFERROR(MATCH(Survey!I23,'Start here'!$A$19:$A$22,0),"")) | H22: =IF(Survey!J23="","",IFERROR(MATCH(Survey!J23,'Start here'!$A$19:$A$22,0),"")) | I22: =IF(AND(ISNUMBER(C22),C$31>0),C22/C$31,"") | J22: =IF(AND(ISNUMBER(D22),D$31>0),D22/D$31,"") | K22: =IF(AND(ISNUMBER(E22),E$31>0),E22/E$31,"") | L22: =IF($L$31=0,"",(IF(ISNUMBER(I22),'Start here'!$B$14*I22,0)+IF(ISNUMBER(J22),'Start here'!$B$15*J22,0)+IF(ISNUMBER(K22),'Start here'!$B$16*K22,0))/$L$31) | M22: =IF(COUNT(F22:H22)>=2,MAX(F22:H22)-MIN(F22:H22),"") | N22: =IF(L22="","",SUMIF($H$11:$H$14,A22,$L$11:$L$14)-SUMIF($I$11:$I$14,A22,$L$11:$L$14)) | O22: =IF(L22="","",MAX(0,L22+N22+N(Results!G21)/100)) | P22: =IF(Results!K21="","",ABS(Results!K21)+A22/1000000000) | Q22: =IF(N(M22)>=2,"Q15 "&B22&" — 2+ levels apart ("&"Mum "&IF(Survey!H23="","–",UPPER(Survey!H23))&", Dad "&IF(Survey!I23="","–",UPPER(Survey!I23))&", Me "&IF(Survey!J23="","–",UPPER(Survey!J23))&")","")
A23: 4 | B23: =Survey!C24 -> Beach | C23: =IF(Survey!H24="","",IFERROR(INDEX('Start here'!$C$19:$C$22,MATCH(Survey!H24,'Start here'!$A$19:$A$22,0)),"")) | D23: =IF(Survey!I24="","",IFERROR(INDEX('Start here'!$C$19:$C$22,MATCH(Survey!I24,'Start here'!$A$19:$A$22,0)),"")) | E23: =IF(Survey!J24="","",IFERROR(INDEX('Start here'!$C$19:$C$22,MATCH(Survey!J24,'Start here'!$A$19:$A$22,0)),"")) | F23: =IF(Survey!H24="","",IFERROR(MATCH(Survey!H24,'Start here'!$A$19:$A$22,0),"")) | G23: =IF(Survey!I24="","",IFERROR(MATCH(Survey!I24,'Start here'!$A$19:$A$22,0),"")) | H23: =IF(Survey!J24="","",IFERROR(MATCH(Survey!J24,'Start here'!$A$19:$A$22,0),"")) | I23: =IF(AND(ISNUMBER(C23),C$31>0),C23/C$31,"") | J23: =IF(AND(ISNUMBER(D23),D$31>0),D23/D$31,"") | K23: =IF(AND(ISNUMBER(E23),E$31>0),E23/E$31,"") | L23: =IF($L$31=0,"",(IF(ISNUMBER(I23),'Start here'!$B$14*I23,0)+IF(ISNUMBER(J23),'Start here'!$B$15*J23,0)+IF(ISNUMBER(K23),'Start here'!$B$16*K23,0))/$L$31) | M23: =IF(COUNT(F23:H23)>=2,MAX(F23:H23)-MIN(F23:H23),"") | N23: =IF(L23="","",SUMIF($H$11:$H$14,A23,$L$11:$L$14)-SUMIF($I$11:$I$14,A23,$L$11:$L$14)) | O23: =IF(L23="","",MAX(0,L23+N23+N(Results!G22)/100)) | P23: =IF(Results!K22="","",ABS(Results!K22)+A23/1000000000) | Q23: =IF(N(M23)>=2,"Q15 "&B23&" — 2+ levels apart ("&"Mum "&IF(Survey!H24="","–",UPPER(Survey!H24))&", Dad "&IF(Survey!I24="","–",UPPER(Survey!I24))&", Me "&IF(Survey!J24="","–",UPPER(Survey!J24))&")","")
A24: 5 | B24: =Survey!C25 -> Hospital nearby | C24: =IF(Survey!H25="","",IFERROR(INDEX('Start here'!$C$19:$C$22,MATCH(Survey!H25,'Start here'!$A$19:$A$22,0)),"")) | D24: =IF(Survey!I25="","",IFERROR(INDEX('Start here'!$C$19:$C$22,MATCH(Survey!I25,'Start here'!$A$19:$A$22,0)),"")) | E24: =IF(Survey!J25="","",IFERROR(INDEX('Start here'!$C$19:$C$22,MATCH(Survey!J25,'Start here'!$A$19:$A$22,0)),"")) | F24: =IF(Survey!H25="","",IFERROR(MATCH(Survey!H25,'Start here'!$A$19:$A$22,0),"")) | G24: =IF(Survey!I25="","",IFERROR(MATCH(Survey!I25,'Start here'!$A$19:$A$22,0),"")) | H24: =IF(Survey!J25="","",IFERROR(MATCH(Survey!J25,'Start here'!$A$19:$A$22,0),"")) | I24: =IF(AND(ISNUMBER(C24),C$31>0),C24/C$31,"") | J24: =IF(AND(ISNUMBER(D24),D$31>0),D24/D$31,"") | K24: =IF(AND(ISNUMBER(E24),E$31>0),E24/E$31,"") | L24: =IF($L$31=0,"",(IF(ISNUMBER(I24),'Start here'!$B$14*I24,0)+IF(ISNUMBER(J24),'Start here'!$B$15*J24,0)+IF(ISNUMBER(K24),'Start here'!$B$16*K24,0))/$L$31) | M24: =IF(COUNT(F24:H24)>=2,MAX(F24:H24)-MIN(F24:H24),"") | N24: =IF(L24="","",SUMIF($H$11:$H$14,A24,$L$11:$L$14)-SUMIF($I$11:$I$14,A24,$L$11:$L$14)) | O24: =IF(L24="","",MAX(0,L24+N24+N(Results!G23)/100)) | P24: =IF(Results!K23="","",ABS(Results!K23)+A24/1000000000) | Q24: =IF(N(M24)>=2,"Q15 "&B24&" — 2+ levels apart ("&"Mum "&IF(Survey!H25="","–",UPPER(Survey!H25))&", Dad "&IF(Survey!I25="","–",UPPER(Survey!I25))&", Me "&IF(Survey!J25="","–",UPPER(Survey!J25))&")","")
A25: 6 | B25: =Survey!C26 -> Train or bus | C25: =IF(Survey!H26="","",IFERROR(INDEX('Start here'!$C$19:$C$22,MATCH(Survey!H26,'Start here'!$A$19:$A$22,0)),"")) | D25: =IF(Survey!I26="","",IFERROR(INDEX('Start here'!$C$19:$C$22,MATCH(Survey!I26,'Start here'!$A$19:$A$22,0)),"")) | E25: =IF(Survey!J26="","",IFERROR(INDEX('Start here'!$C$19:$C$22,MATCH(Survey!J26,'Start here'!$A$19:$A$22,0)),"")) | F25: =IF(Survey!H26="","",IFERROR(MATCH(Survey!H26,'Start here'!$A$19:$A$22,0),"")) | G25: =IF(Survey!I26="","",IFERROR(MATCH(Survey!I26,'Start here'!$A$19:$A$22,0),"")) | H25: =IF(Survey!J26="","",IFERROR(MATCH(Survey!J26,'Start here'!$A$19:$A$22,0),"")) | I25: =IF(AND(ISNUMBER(C25),C$31>0),C25/C$31,"") | J25: =IF(AND(ISNUMBER(D25),D$31>0),D25/D$31,"") | K25: =IF(AND(ISNUMBER(E25),E$31>0),E25/E$31,"") | L25: =IF($L$31=0,"",(IF(ISNUMBER(I25),'Start here'!$B$14*I25,0)+IF(ISNUMBER(J25),'Start here'!$B$15*J25,0)+IF(ISNUMBER(K25),'Start here'!$B$16*K25,0))/$L$31) | M25: =IF(COUNT(F25:H25)>=2,MAX(F25:H25)-MIN(F25:H25),"") | N25: =IF(L25="","",SUMIF($H$11:$H$14,A25,$L$11:$L$14)-SUMIF($I$11:$I$14,A25,$L$11:$L$14)) | O25: =IF(L25="","",MAX(0,L25+N25+N(Results!G24)/100)) | P25: =IF(Results!K24="","",ABS(Results!K24)+A25/1000000000) | Q25: =IF(N(M25)>=2,"Q15 "&B25&" — 2+ levels apart ("&"Mum "&IF(Survey!H26="","–",UPPER(Survey!H26))&", Dad "&IF(Survey!I26="","–",UPPER(Survey!I26))&", Me "&IF(Survey!J26="","–",UPPER(Survey!J26))&")","")
A26: 7 | B26: =Survey!C27 -> Shops and doctor nearby | C26: =IF(Survey!H27="","",IFERROR(INDEX('Start here'!$C$19:$C$22,MATCH(Survey!H27,'Start here'!$A$19:$A$22,0)),"")) | D26: =IF(Survey!I27="","",IFERROR(INDEX('Start here'!$C$19:$C$22,MATCH(Survey!I27,'Start here'!$A$19:$A$22,0)),"")) | E26: =IF(Survey!J27="","",IFERROR(INDEX('Start here'!$C$19:$C$22,MATCH(Survey!J27,'Start here'!$A$19:$A$22,0)),"")) | F26: =IF(Survey!H27="","",IFERROR(MATCH(Survey!H27,'Start here'!$A$19:$A$22,0),"")) | G26: =IF(Survey!I27="","",IFERROR(MATCH(Survey!I27,'Start here'!$A$19:$A$22,0),"")) | H26: =IF(Survey!J27="","",IFERROR(MATCH(Survey!J27,'Start here'!$A$19:$A$22,0),"")) | I26: =IF(AND(ISNUMBER(C26),C$31>0),C26/C$31,"") | J26: =IF(AND(ISNUMBER(D26),D$31>0),D26/D$31,"") | K26: =IF(AND(ISNUMBER(E26),E$31>0),E26/E$31,"") | L26: =IF($L$31=0,"",(IF(ISNUMBER(I26),'Start here'!$B$14*I26,0)+IF(ISNUMBER(J26),'Start here'!$B$15*J26,0)+IF(ISNUMBER(K26),'Start here'!$B$16*K26,0))/$L$31) | M26: =IF(COUNT(F26:H26)>=2,MAX(F26:H26)-MIN(F26:H26),"") | N26: =IF(L26="","",SUMIF($H$11:$H$14,A26,$L$11:$L$14)-SUMIF($I$11:$I$14,A26,$L$11:$L$14)) | O26: =IF(L26="","",MAX(0,L26+N26+N(Results!G25)/100)) | P26: =IF(Results!K25="","",ABS(Results!K25)+A26/1000000000) | Q26: =IF(N(M26)>=2,"Q15 "&B26&" — 2+ levels apart ("&"Mum "&IF(Survey!H27="","–",UPPER(Survey!H27))&", Dad "&IF(Survey!I27="","–",UPPER(Survey!I27))&", Me "&IF(Survey!J27="","–",UPPER(Survey!J27))&")","")
A27: 8 | B27: =Survey!C28 -> Village character | C27: =IF(Survey!H28="","",IFERROR(INDEX('Start here'!$C$19:$C$22,MATCH(Survey!H28,'Start here'!$A$19:$A$22,0)),"")) | D27: =IF(Survey!I28="","",IFERROR(INDEX('Start here'!$C$19:$C$22,MATCH(Survey!I28,'Start here'!$A$19:$A$22,0)),"")) | E27: =IF(Survey!J28="","",IFERROR(INDEX('Start here'!$C$19:$C$22,MATCH(Survey!J28,'Start here'!$A$19:$A$22,0)),"")) | F27: =IF(Survey!H28="","",IFERROR(MATCH(Survey!H28,'Start here'!$A$19:$A$22,0),"")) | G27: =IF(Survey!I28="","",IFERROR(MATCH(Survey!I28,'Start here'!$A$19:$A$22,0),"")) | H27: =IF(Survey!J28="","",IFERROR(MATCH(Survey!J28,'Start here'!$A$19:$A$22,0),"")) | I27: =IF(AND(ISNUMBER(C27),C$31>0),C27/C$31,"") | J27: =IF(AND(ISNUMBER(D27),D$31>0),D27/D$31,"") | K27: =IF(AND(ISNUMBER(E27),E$31>0),E27/E$31,"") | L27: =IF($L$31=0,"",(IF(ISNUMBER(I27),'Start here'!$B$14*I27,0)+IF(ISNUMBER(J27),'Start here'!$B$15*J27,0)+IF(ISNUMBER(K27),'Start here'!$B$16*K27,0))/$L$31) | M27: =IF(COUNT(F27:H27)>=2,MAX(F27:H27)-MIN(F27:H27),"") | N27: =IF(L27="","",SUMIF($H$11:$H$14,A27,$L$11:$L$14)-SUMIF($I$11:$I$14,A27,$L$11:$L$14)) | O27: =IF(L27="","",MAX(0,L27+N27+N(Results!G26)/100)) | P27: =IF(Results!K26="","",ABS(Results!K26)+A27/1000000000) | Q27: =IF(N(M27)>=2,"Q15 "&B27&" — 2+ levels apart ("&"Mum "&IF(Survey!H28="","–",UPPER(Survey!H28))&", Dad "&IF(Survey!I28="","–",UPPER(Survey!I28))&", Me "&IF(Survey!J28="","–",UPPER(Survey!J28))&")","")
A28: 9 | B28: =Survey!C29 -> Price | C28: =IF(Survey!H29="","",IFERROR(INDEX('Start here'!$C$19:$C$22,MATCH(Survey!H29,'Start here'!$A$19:$A$22,0)),"")) | D28: =IF(Survey!I29="","",IFERROR(INDEX('Start here'!$C$19:$C$22,MATCH(Survey!I29,'Start here'!$A$19:$A$22,0)),"")) | E28: =IF(Survey!J29="","",IFERROR(INDEX('Start here'!$C$19:$C$22,MATCH(Survey!J29,'Start here'!$A$19:$A$22,0)),"")) | F28: =IF(Survey!H29="","",IFERROR(MATCH(Survey!H29,'Start here'!$A$19:$A$22,0),"")) | G28: =IF(Survey!I29="","",IFERROR(MATCH(Survey!I29,'Start here'!$A$19:$A$22,0),"")) | H28: =IF(Survey!J29="","",IFERROR(MATCH(Survey!J29,'Start here'!$A$19:$A$22,0),"")) | I28: =IF(AND(ISNUMBER(C28),C$31>0),C28/C$31,"") | J28: =IF(AND(ISNUMBER(D28),D$31>0),D28/D$31,"") | K28: =IF(AND(ISNUMBER(E28),E$31>0),E28/E$31,"") | L28: =IF($L$31=0,"",(IF(ISNUMBER(I28),'Start here'!$B$14*I28,0)+IF(ISNUMBER(J28),'Start here'!$B$15*J28,0)+IF(ISNUMBER(K28),'Start here'!$B$16*K28,0))/$L$31) | M28: =IF(COUNT(F28:H28)>=2,MAX(F28:H28)-MIN(F28:H28),"") | N28: =IF(L28="","",SUMIF($H$11:$H$14,A28,$L$11:$L$14)-SUMIF($I$11:$I$14,A28,$L$11:$L$14)) | O28: =IF(L28="","",MAX(0,L28+N28+N(Results!G27)/100)) | P28: =IF(Results!K27="","",ABS(Results!K27)+A28/1000000000) | Q28: =IF(N(M28)>=2,"Q15 "&B28&" — 2+ levels apart ("&"Mum "&IF(Survey!H29="","–",UPPER(Survey!H29))&", Dad "&IF(Survey!I29="","–",UPPER(Survey!I29))&", Me "&IF(Survey!J29="","–",UPPER(Survey!J29))&")","")
A29: 10 | B29: =Survey!C30 -> Easy trip to the city (work, outings) | C29: =IF(Survey!H30="","",IFERROR(INDEX('Start here'!$C$19:$C$22,MATCH(Survey!H30,'Start here'!$A$19:$A$22,0)),"")) | D29: =IF(Survey!I30="","",IFERROR(INDEX('Start here'!$C$19:$C$22,MATCH(Survey!I30,'Start here'!$A$19:$A$22,0)),"")) | E29: =IF(Survey!J30="","",IFERROR(INDEX('Start here'!$C$19:$C$22,MATCH(Survey!J30,'Start here'!$A$19:$A$22,0)),"")) | F29: =IF(Survey!H30="","",IFERROR(MATCH(Survey!H30,'Start here'!$A$19:$A$22,0),"")) | G29: =IF(Survey!I30="","",IFERROR(MATCH(Survey!I30,'Start here'!$A$19:$A$22,0),"")) | H29: =IF(Survey!J30="","",IFERROR(MATCH(Survey!J30,'Start here'!$A$19:$A$22,0),"")) | I29: =IF(AND(ISNUMBER(C29),C$31>0),C29/C$31,"") | J29: =IF(AND(ISNUMBER(D29),D$31>0),D29/D$31,"") | K29: =IF(AND(ISNUMBER(E29),E$31>0),E29/E$31,"") | L29: =IF($L$31=0,"",(IF(ISNUMBER(I29),'Start here'!$B$14*I29,0)+IF(ISNUMBER(J29),'Start here'!$B$15*J29,0)+IF(ISNUMBER(K29),'Start here'!$B$16*K29,0))/$L$31) | M29: =IF(COUNT(F29:H29)>=2,MAX(F29:H29)-MIN(F29:H29),"") | N29: =IF(L29="","",SUMIF($H$11:$H$14,A29,$L$11:$L$14)-SUMIF($I$11:$I$14,A29,$L$11:$L$14)) | O29: =IF(L29="","",MAX(0,L29+N29+N(Results!G28)/100)) | P29: =IF(Results!K28="","",ABS(Results!K28)+A29/1000000000) | Q29: =IF(N(M29)>=2,"Q15 "&B29&" — 2+ levels apart ("&"Mum "&IF(Survey!H30="","–",UPPER(Survey!H30))&", Dad "&IF(Survey!I30="","–",UPPER(Survey!I30))&", Me "&IF(Survey!J30="","–",UPPER(Survey!J30))&")","")
A31: Totals | C31: =SUM(C20:C29) -> 0 | D31: =SUM(D20:D29) -> 0 | E31: =SUM(E20:E29) -> 0 | K31: Say total | L31: =(C31>0)*'Start here'!$B$14+(D31>0)*'Start here'!$B$15+(E31>0)*'Start here'!$B$16 -> 0
A35: Label | B35: Survey row | C35: Distinct answers | D35: Type | E35: Mum level | F35: Dad level | G35: Me level | H35: Spread | I35: Mum≠Dad | J35: Discuss text
A36: Q3 Budget | B36: 7 | C36: =SUMPRODUCT((Survey!H7:J7<>"")/COUNTIF(Survey!H7:J7,Survey!H7:J7&"")) -> 0 | D36: ordered | E36: =IF(Survey!H7="","",IFERROR(MATCH(Survey!H7,'Start here'!$A$19:$A$22,0),"")) | F36: =IF(Survey!I7="","",IFERROR(MATCH(Survey!I7,'Start here'!$A$19:$A$22,0),"")) | G36: =IF(Survey!J7="","",IFERROR(MATCH(Survey!J7,'Start here'!$A$19:$A$22,0),"")) | H36: =IF(COUNT(E36:G36)>=2,MAX(E36:G36)-MIN(E36:G36),"") | I36: =AND(Survey!H7<>"",Survey!I7<>"",Survey!H7<>Survey!I7) -> FALSE | J36: =IF(AND(D36="ordered",N(H36)>=2),A36&" — big gap ("&"Mum "&IF(Survey!H7="","–",UPPER(Survey!H7))&", Dad "&IF(Survey!I7="","–",UPPER(Survey!I7))&", Me "&IF(Survey!J7="","–",UPPER(Survey!J7))&")",IF(AND(D36="pair",I36),A36&" — Mum and Dad differ ("&"Mum "&IF(Survey!H7="","–",UPPER(Survey!H7))&", Dad "&IF(Survey!I7="","–",UPPER(Survey!I7))&", Me "&IF(Survey!J7="","–",UPPER(Survey!J7))&")",""))
A37: Q4 Glen Waverley drive | B37: 8 | C37: =SUMPRODUCT((Survey!H8:J8<>"")/COUNTIF(Survey!H8:J8,Survey!H8:J8&"")) -> 0 | D37: ordered | E37: =IF(Survey!H8="","",IFERROR(MATCH(Survey!H8,'Start here'!$A$19:$A$22,0),"")) | F37: =IF(Survey!I8="","",IFERROR(MATCH(Survey!I8,'Start here'!$A$19:$A$22,0),"")) | G37: =IF(Survey!J8="","",IFERROR(MATCH(Survey!J8,'Start here'!$A$19:$A$22,0),"")) | H37: =IF(COUNT(E37:G37)>=2,MAX(E37:G37)-MIN(E37:G37),"") | I37: =AND(Survey!H8<>"",Survey!I8<>"",Survey!H8<>Survey!I8) -> FALSE | J37: =IF(AND(D37="ordered",N(H37)>=2),A37&" — big gap ("&"Mum "&IF(Survey!H8="","–",UPPER(Survey!H8))&", Dad "&IF(Survey!I8="","–",UPPER(Survey!I8))&", Me "&IF(Survey!J8="","–",UPPER(Survey!J8))&")",IF(AND(D37="pair",I37),A37&" — Mum and Dad differ ("&"Mum "&IF(Survey!H8="","–",UPPER(Survey!H8))&", Dad "&IF(Survey!I8="","–",UPPER(Survey!I8))&", Me "&IF(Survey!J8="","–",UPPER(Survey!J8))&")",""))
A38: Q5 Hospital drive | B38: 9 | C38: =SUMPRODUCT((Survey!H9:J9<>"")/COUNTIF(Survey!H9:J9,Survey!H9:J9&"")) -> 0 | D38: ordered | E38: =IF(Survey!H9="","",IFERROR(MATCH(Survey!H9,'Start here'!$A$19:$A$22,0),"")) | F38: =IF(Survey!I9="","",IFERROR(MATCH(Survey!I9,'Start here'!$A$19:$A$22,0),"")) | G38: =IF(Survey!J9="","",IFERROR(MATCH(Survey!J9,'Start here'!$A$19:$A$22,0),"")) | H38: =IF(COUNT(E38:G38)>=2,MAX(E38:G38)-MIN(E38:G38),"") | I38: =AND(Survey!H9<>"",Survey!I9<>"",Survey!H9<>Survey!I9) -> FALSE | J38: =IF(AND(D38="ordered",N(H38)>=2),A38&" — big gap ("&"Mum "&IF(Survey!H9="","–",UPPER(Survey!H9))&", Dad "&IF(Survey!I9="","–",UPPER(Survey!I9))&", Me "&IF(Survey!J9="","–",UPPER(Survey!J9))&")",IF(AND(D38="pair",I38),A38&" — Mum and Dad differ ("&"Mum "&IF(Survey!H9="","–",UPPER(Survey!H9))&", Dad "&IF(Survey!I9="","–",UPPER(Survey!I9))&", Me "&IF(Survey!J9="","–",UPPER(Survey!J9))&")",""))
